Workbook

Sheet Siniestralidad Yopal  (2)
A1: ID | B1: SOLO_DAÑOS | C1: LESIONADOS | D1: MUERTOS | E1: GRAVEDAD | F1: DIRECCION_ | G1: LATITUD | H1: LONGITUD | I1: COMUNA | J1: AREA | K1: AÑO | L1: MES | M1: FECHA | N1: DIA_DE_LA_SEMANA_ | O1: HORA_ACCIDENTE | P1: VEHICULOS_ACCIDENTADOS | Q1: VEHICULOS_ACCIDENTADOS2 | R1: MOTO | S1: MOTO_CARRO | T1: AUTOMOVIL | U1: CAMPERO | V1: CAMIONETA | W1: MICROBUS | X1: BUS | Y1: BUSETA | Z1: CAMION | AA1: TRACTOCAMION | AB1: VOLQUETA | AC1: BICICLETA | AD1: GENERO_MASCULINO | AE1: GENERO_FEMENINO | AF1: MASCULINO | AG1: FEMENINO | AH1: EDAD_LESIONADOS_CONDUCTOR_1 | AI1: EDAD_LESIONADOS_CONDUCTOR_2 | AJ1: EDAD_LESIONADOS_PASAJERO | AK1: EDAD_LESIONADOS_PEATON | AL1: EDAD_LESIONADO_ACOMÁÑANTE | AM1: EDAD_MUERTO | AN1: HIPOTESIS_1 | AO1: Descripcion_Hipotesis | AP1: HIPOTESIS_2 | AQ1: Descripcion_Hipotesis2 | AR1: Franja_Horaria
A2: 182 | B2: 0 | C2: 0 | D2: 1 | E2: =IF(D2>=1,"FALLECIDO",IF(C2>=1,"LESIONADO",IF(B2>=1,"SOLO DAÑO",""))) -> FALLECIDO | F2: CARRERA 15 # 40 | G2: 5.3189806 | H2: -72.394608 | I2: MOVILIDAD | J2: URBANO | K2: =UPPER(TEXT(M2,"YYYY")) -> 2022 | L2: =UPPER(TEXT(M2,"MMMM")) -> MAYO | M2: 44695 | N2: =UPPER(TEXT(M2,"DDDD")) -> SÁBADO | O2: 0.82638889 | P2: MOTOCICLETA | Q2: AUTOMOVIL | R2: =COUNTIF(Tabla1[[#This Row],[VEHICULOS_ACCIDENTADOS]:[VEHICULOS_ACCIDENTADOS2]],"MOTOCICLETA") -> 1 | S2: =COUNTIF(Tabla1[[#This Row],[VEHICULOS_ACCIDENTADOS]:[VEHICULOS_ACCIDENTADOS2]],"MOTOCARRO") -> 0 | T2: =COUNTIF(Tabla1[[#This Row],[VEHICULOS_ACCIDENTADOS]:[VEHICULOS_ACCIDENTADOS2]],"AUTOMOVIL") -> 1 | U2: =COUNTIF(Tabla1[[#This Row],[VEHICULOS_ACCIDENTADOS]:[VEHICULOS_ACCIDENTADOS2]],"CAMPERO") -> 0 | V2: =COUNTIF(Tabla1[[#This Row],[VEHICULOS_ACCIDENTADOS]:[VEHICULOS_ACCIDENTADOS2]],"CAMIONETA") -> 0 | W2: =COUNTIF(Tabla1[[#This Row],[VEHICULOS_ACCIDENTADOS]:[VEHICULOS_ACCIDENTADOS2]],"MICROBUS") -> 0 | X2: =COUNTIF(Tabla1[[#This Row],[VEHICULOS_ACCIDENTADOS]:[VEHICULOS_ACCIDENTADOS2]],"BUS") -> 0 | Y2: =COUNTIF(Tabla1[[#This Row],[VEHICULOS_ACCIDENTADOS]:[VEHICULOS_ACCIDENTADOS2]],"BUSETA") -> 0 | Z2: =COUNTIF(Tabla1[[#This Row],[VEHICULOS_ACCIDENTADOS]:[VEHICULOS_ACCIDENTADOS2]],"CAMION") -> 0 | AA2: =COUNTIF(Tabla1[[#This Row],[VEHICULOS_ACCIDENTADOS]:[VEHICULOS_ACCIDENTADOS2]],"TRACTOCAMION") -> 0 | AB2: =COUNTIF(Tabla1[[#This Row],[VEHICULOS_ACCIDENTADOS]:[VEHICULOS_ACCIDENTADOS2]],"VOLQUETA") -> 0 | AC2: =COUNTIF(Tabla1[[#This Row],[VEHICULOS_ACCIDENTADOS]:[VEHICULOS_ACCIDENTADOS2]],"BICICLETA") -> 0 | AE2: FEMENINO | AF2: =COUNTIF(Tabla1[[#This Row],[GENERO_MASCULINO]:[GENERO_FEMENINO]],"MASCULINO") -> 0 | AG2: =COUNTIF(Tabla1[[#This Row],[GENERO_MASCULINO]:[GENERO_FEMENINO]],"FEMENINO") -> 1 | AM2: 45 | AN2: 114 | AO2: =IFERROR(((VLOOKUP(Tabla1[[#This Row],[HIPOTESIS_1]],listas!$D$1:$E$105,2,FALSE))),"SIN INFORMACIÓN") -> Embriaguez aparente. | AP2: 141 | AQ2: =IFERROR(((VLOOKUP(Tabla1[[#This Row],[HIPOTESIS_2]],listas!$D$1:$E$105,2,FALSE))),"") -> Vehículo mal estacionado. | AR2: =IF(HOUR(Tabla1[[#This Row],[HORA_ACCIDENTE]])<6,"MAÑANA", IF(HOUR(Tabla1[[#This Row],[HORA_ACCIDENTE]])<12,"MAÑANA", IF(HOUR(Tabla1[[#This Row],[HORA_ACCIDENTE]])<18,"TARDE","NOCHE"))) -> NOCHE
A3: 789 | B3: 0 | C3: 1 | D3: 0 | E3: =IF(D3>=1,"FALLECIDO",IF(C3>=1,"LESIONADO",IF(B3>=1,"SOLO DAÑO",""))) -> LESIONADO | F3: CARRERA 15 DIAGONAL 47 | G3: 5.3150639 | H3: -72.393893 | I3: MOVILIDAD | J3: URBANO | K3: =UPPER(TEXT(M3,"YYYY")) -> 2024 | L3: =UPPER(TEXT(M3,"MMMM")) -> OCTUBRE | M3: 45576 | N3: =UPPER(TEXT(M3,"DDDD")) -> VIERNES | O3: 0.32291667 | P3: MOTOCICLETA | Q3: AUTOMOVIL | R3: =COUNTIF(Tabla1[[#This Row],[VEHICULOS_ACCIDENTADOS]:[VEHICULOS_ACCIDENTADOS2]],"MOTOCICLETA") -> 1 | S3: =COUNTIF(Tabla1[[#This Row],[VEHICULOS_ACCIDENTADOS]:[VEHICULOS_ACCIDENTADOS2]],"MOTOCARRO") -> 0 | T3: =COUNTIF(Tabla1[[#This Row],[VEHICULOS_ACCIDENTADOS]:[VEHICULOS_ACCIDENTADOS2]],"AUTOMOVIL") -> 1 | U3: =COUNTIF(Tabla1[[#This Row],[VEHICULOS_ACCIDENTADOS]:[VEHICULOS_ACCIDENTADOS2]],"CAMPERO") -> 0 | V3: =COUNTIF(Tabla1[[#This Row],[VEHICULOS_ACCIDENTADOS]:[VEHICULOS_ACCIDENTADOS2]],"CAMIONETA") -> 0 | W3: =COUNTIF(Tabla1[[#This Row],[VEHICULOS_ACCIDENTADOS]:[VEHICULOS_ACCIDENTADOS2]],"MICROBUS") -> 0 | X3: =COUNTIF(Tabla1[[#This Row],[VEHICULOS_ACCIDENTADOS]:[VEHICULOS_ACCIDENTADOS2]],"BUS") -> 0 | Y3: =COUNTIF(Tabla1[[#This Row],[VEHICULOS_ACCIDENTADOS]:[VEHICULOS_ACCIDENTADOS2]],"BUSETA") -> 0 | Z3: =COUNTIF(Tabla1[[#This Row],[VEHICULOS_ACCIDENTADOS]:[VEHICULOS_ACCIDENTADOS2]],"CAMION") -> 0 | AA3: =COUNTIF(Tabla1[[#This Row],[VEHICULOS_ACCIDENTADOS]:[VEHICULOS_ACCIDENTADOS2]],"TRACTOCAMION") -> 0 | AB3: =COUNTIF(Tabla1[[#This Row],[VEHICULOS_ACCIDENTADOS]:[VEHICULOS_ACCIDENTADOS2]],"VOLQUETA") -> 0 | AC3: =COUNTIF(Tabla1[[#This Row],[VEHICULOS_ACCIDENTADOS]:[VEHICULOS_ACCIDENTADOS2]],"BICICLETA") -> 0 | AD3: MASCULINO | AF3: =COUNTIF(Tabla1[[#This Row],[GENERO_MASCULINO]:[GENERO_FEMENINO]],"MASCULINO") -> 1 | AG3: =COUNTIF(Tabla1[[#This Row],[GENERO_MASCULINO]:[GENERO_FEMENINO]],"FEMENINO") -> 0 | AH3: 27 | AI3: 50 | AN3: 121 | AO3: =IFERROR(((VLOOKUP(Tabla1[[#This Row],[HIPOTESIS_1]],listas!$D$1:$E$105,2,FALSE))),"SIN INFORMACIÓN") -> No mantener distancia de seguridad. | AP3: 141 | AQ3: =IFERROR(((VLOOKUP(Tabla1[[#This Row],[HIPOTESIS_2]],listas!$D$1:$E$105,2,FALSE))),"") -> Vehículo mal estacionado. | AR3: =IF(HOUR(Tabla1[[#This Row],[HORA_ACCIDENTE]])<6,"MAÑANA", IF(HOUR(Tabla1[[#This Row],[HORA_ACCIDENTE]])<12,"MAÑANA", IF(HOUR(Tabla1[[#This Row],[HORA_ACCIDENTE]])<18,"TARDE","NOCHE"))) -> MAÑANA
A4: 923 | B4: 0 | C4: 0 | D4: 1 | E4: =IF(D4>=1,"FALLECIDO",IF(C4>=1,"LESIONADO",IF(B4>=1,"SOLO DAÑO",""))) -> FALLECIDO | F4: DIAGONAL 47 ENTRE CARRERAS 4-5 | G4: 5.308856 | H4: -72.405289 | I4: MOVILIDAD | J4: URBANO | K4: =UPPER(TEXT(M4,"YYYY")) -> 2025 | L4: =UPPER(TEXT(M4,"MMMM")) -> ABRIL | M4: 45751 | N4: =UPPER(TEXT(M4,"DDDD")) -> VIERNES | O4: 0.84375 | P4: MOTOCICLETA | Q4: CAMION | R4: =COUNTIF(Tabla1[[#This Row],[VEHICULOS_ACCIDENTADOS]:[VEHICULOS_ACCIDENTADOS2]],"MOTOCICLETA") -> 1 | S4: =COUNTIF(Tabla1[[#This Row],[VEHICULOS_ACCIDENTADOS]:[VEHICULOS_ACCIDENTADOS2]],"MOTOCARRO") -> 0 | T4: =COUNTIF(Tabla1[[#This Row],[VEHICULOS_ACCIDENTADOS]:[VEHICULOS_ACCIDENTADOS2]],"AUTOMOVIL") -> 0 | U4: =COUNTIF(Tabla1[[#This Row],[VEHICULOS_ACCIDENTADOS]:[VEHICULOS_ACCIDENTADOS2]],"CAMPERO") -> 0 | V4: =COUNTIF(Tabla1[[#This Row],[VEHICULOS_ACCIDENTADOS]:[VEHICULOS_ACCIDENTADOS2]],"CAMIONETA") -> 0 | W4: =COUNTIF(Tabla1[[#This Row],[VEHICULOS_ACCIDENTADOS]:[VEHICULOS_ACCIDENTADOS2]],"MICROBUS") -> 0 | X4: =COUNTIF(Tabla1[[#This Row],[VEHICULOS_ACCIDENTADOS]:[VEHICULOS_ACCIDENTADOS2]],"BUS") -> 0 | Y4: =COUNTIF(Tabla1[[#This Row],[VEHICULOS_ACCIDENTADOS]:[VEHICULOS_ACCIDENTADOS2]],"BUSETA") -> 0 | Z4: =COUNTIF(Tabla1[[#This Row],[VEHICULOS_ACCIDENTADOS]:[VEHICULOS_ACCIDENTADOS2]],"CAMION") -> 0 | AA4: =COUNTIF(Tabla1[[#This Row],[VEHICULOS_ACCIDENTADOS]:[VEHICULOS_ACCIDENTADOS2]],"TRACTOCAMION") -> 0 | AB4: =COUNTIF(Tabla1[[#This Row],[VEHICULOS_ACCIDENTADOS]:[VEHICULOS_ACCIDENTADOS2]],"VOLQUETA") -> 0 | AC4: =COUNTIF(Tabla1[[#This Row],[VEHICULOS_ACCIDENTADOS]:[VEHICULOS_ACCIDENTADOS2]],"BICICLETA") -> 0 | AD4: MASCULINO | AE4: N/A | AF4: =COUNTIF(Tabla1[[#This Row],[GENERO_MASCULINO]:[GENERO_FEMENINO]],"MASCULINO") -> 1 | AG4: =COUNTIF(Tabla1[[#This Row],[GENERO_MASCULINO]:[GENERO_FEMENINO]],"FEMENINO") -> 0 | AH4: 44 | AN4: 114 | AO4: =IFERROR(((VLOOKUP(Tabla1[[#This Row],[HIPOTESIS_1]],listas!$D$1:$E$105,2,FALSE))),"SIN INFORMACIÓN") -> Embriaguez aparente. | AP4: 141 | AQ4: =IFERROR(((VLOOKUP(Tabla1[[#This Row],[HIPOTESIS_2]],listas!$D$1:$E$105,2,FALSE))),"") -> Vehículo mal estacionado. | AR4: =IF(HOUR(Tabla1[[#This Row],[HORA_ACCIDENTE]])<6,"MAÑANA", IF(HOUR(Tabla1[[#This Row],[HORA_ACCIDENTE]])<12,"MAÑANA", IF(HOUR(Tabla1[[#This Row],[HORA_ACCIDENTE]])<18,"TARDE","NOCHE"))) -> NOCHE
A5: 346 | B5: 0 | C5: 3 | D5: 0 | E5: =IF(D5>=1,"FALLECIDO",IF(C5>=1,"LESIONADO",IF(B5>=1,"SOLO DAÑO",""))) -> LESIONADO | F5: TRANSVERSAL 15 CALLE 35 | G5: 5.3245444 | H5: -72.393758 | I5: MOVILIDAD | J5: URBANO | K5: =UPPER(TEXT(M5,"YYYY")) -> 2022 | L5: =UPPER(TEXT(M5,"MMMM")) -> OCTUBRE | M5: 44864 | N5: =UPPER(TEXT(M5,"DDDD")) -> DOMINGO | O5: 0.15625 | P5: MOTOCICLETA | Q5: AUTOMOVIL | R5: =COUNTIF(Tabla1[[#This Row],[VEHICULOS_ACCIDENTADOS]:[VEHICULOS_ACCIDENTADOS2]],"MOTOCICLETA") -> 1 | S5: =COUNTIF(Tabla1[[#This Row],[VEHICULOS_ACCIDENTADOS]:[VEHICULOS_ACCIDENTADOS2]],"MOTOCARRO") -> 0 | T5: =COUNTIF(Tabla1[[#This Row],[VEHICULOS_ACCIDENTADOS]:[VEHICULOS_ACCIDENTADOS2]],"AUTOMOVIL") -> 1 | U5: =COUNTIF(Tabla1[[#This Row],[VEHICULOS_ACCIDENTADOS]:[VEHICULOS_ACCIDENTADOS2]],"CAMPERO") -> 0 | V5: =COUNTIF(Tabla1[[#This Row],[VEHICULOS_ACCIDENTADOS]:[VEHICULOS_ACCIDENTADOS2]],"CAMIONETA") -> 0 | W5: =COUNTIF(Tabla1[[#This Row],[VEHICULOS_ACCIDENTADOS]:[VEHICULOS_ACCIDENTADOS2]],"MICROBUS") -> 0 | X5: =COUNTIF(Tabla1[[#This Row],[VEHICULOS_ACCIDENTADOS]:[VEHICULOS_ACCIDENTADOS2]],"BUS") -> 0 | Y5: =COUNTIF(Tabla1[[#This Row],[VEHICULOS_ACCIDENTADOS]:[VEHICULOS_ACCIDENTADOS2]],"BUSETA") -> 0 | Z5: =COUNTIF(Tabla1[[#This Row],[VEHICULOS_ACCIDENTADOS]:[VEHICULOS_ACCIDENTADOS2]],"CAMION") -> 0 | AA5: =COUNTIF(Tabla1[[#This Row],[VEHICULOS_ACCIDENTADOS]:[VEHICULOS_ACCIDENTADOS2]],"TRACTOCAMION") -> 0 | AB5: =COUNTIF(Tabla1[[#This Row],[VEHICULOS_ACCIDENTADOS]:[VEHICULOS_ACCIDENTADOS2]],"VOLQUETA") -> 0 | AC5: =COUNTIF(Tabla1[[#This Row],[VEHICULOS_ACCIDENTADOS]:[VEHICULOS_ACCIDENTADOS2]],"BICICLETA") -> 0 | AD5: MASCULINO | AF5: =COUNTIF(Tabla1[[#This Row],[GENERO_MASCULINO]:[GENERO_FEMENINO]],"MASCULINO") -> 1 | AG5: =COUNTIF(Tabla1[[#This Row],[GENERO_MASCULINO]:[GENERO_FEMENINO]],"FEMENINO") -> 0 | AH5: 30 | AK5: 19 | AN5: 114 | AO5: =IFERROR(((VLOOKUP(Tabla1[[#This Row],[HIPOTESIS_1]],listas!$D$1:$E$105,2,FALSE))),"SIN INFORMACIÓN") -> Embriaguez aparente. | AP5: 141 | AQ5: =IFERROR(((VLOOKUP(Tabla1[[#This Row],[HIPOTESIS_2]],listas!$D$1:$E$105,2,FALSE))),"") -> Vehículo mal estacionado. | AR5: =IF(HOUR(Tabla1[[#This Row],[HORA_ACCIDENTE]])<6,"MAÑANA", IF(HOUR(Tabla1[[#This Row],[HORA_ACCIDENTE]])<12,"MAÑANA", IF(HOUR(Tabla1[[#This Row],[HORA_ACCIDENTE]])<18,"TARDE","NOCHE"))) -> MAÑANA
A6: 1065 | B6: 0 | C6: 3 | D6: 0 | E6: =IF(D6>=1,"FALLECIDO",IF(C6>=1,"LESIONADO",IF(B6>=1,"SOLO DAÑO",""))) -> LESIONADO | F6: CARRERA 14 N # CALLE 25 | G6: 5.33217833 | H6: -72.39902 | I6: MOVILIDAD | J6: URBANO | K6: =UPPER(TEXT(M6,"YYYY")) -> 2025 | L6: =UPPER(TEXT(M6,"MMMM")) -> SEPTIEMBRE | M6: 45912 | N6: =UPPER(TEXT(M6,"DDDD")) -> VIERNES | O6: 0.62847222 | P6: MOTOCICLETA | Q6: BICICLETA | R6: =COUNTIF(Tabla1[[#This Row],[VEHICULOS_ACCIDENTADOS]:[VEHICULOS_ACCIDENTADOS2]],"MOTOCICLETA") -> 1 | S6: =COUNTIF(Tabla1[[#This Row],[VEHICULOS_ACCIDENTADOS]:[VEHICULOS_ACCIDENTADOS2]],"MOTOCARRO") -> 0 | T6: =COUNTIF(Tabla1[[#This Row],[VEHICULOS_ACCIDENTADOS]:[VEHICULOS_ACCIDENTADOS2]],"AUTOMOVIL") -> 0 | U6: =COUNTIF(Tabla1[[#This Row],[VEHICULOS_ACCIDENTADOS]:[VEHICULOS_ACCIDENTADOS2]],"CAMPERO") -> 0 | V6: =COUNTIF(Tabla1[[#This Row],[VEHICULOS_ACCIDENTADOS]:[VEHICULOS_ACCIDENTADOS2]],"CAMIONETA") -> 0 | W6: =COUNTIF(Tabla1[[#This Row],[VEHICULOS_ACCIDENTADOS]:[VEHICULOS_ACCIDENTADOS2]],"MICROBUS") -> 0 | X6: =COUNTIF(Tabla1[[#This Row],[VEHICULOS_ACCIDENTADOS]:[VEHICULOS_ACCIDENTADOS2]],"BUS") -> 0 | Y6: =COUNTIF(Tabla1[[#This Row],[VEHICULOS_ACCIDENTADOS]:[VEHICULOS_ACCIDENTADOS2]],"BUSETA") -> 0 | Z6: =COUNTIF(Tabla1[[#This Row],[VEHICULOS_ACCIDENTADOS]:[VEHICULOS_ACCIDENTADOS2]],"CAMION") -> 0 | AA6: =COUNTIF(Tabla1[[#This Row],[VEHICULOS_ACCIDENTADOS]:[VEHICULOS_ACCIDENTADOS2]],"TRACTOCAMION") -> 0 | AB6: =COUNTIF(Tabla1[[#This Row],[VEHICULOS_ACCIDENTADOS]:[VEHICULOS_ACCIDENTADOS2]],"VOLQUETA") -> 0 | AC6: =COUNTIF(Tabla1[[#This Row],[VEHICULOS_ACCIDENTADOS]:[VEHICULOS_ACCIDENTADOS2]],"BICICLETA") -> 1 | AD6: FEMENINO | AE6: MASCULINO | AF6: =COUNTIF(Tabla1[[#This Row],[GENERO_MASCULINO]:[GENERO_FEMENINO]],"MASCULINO") -> 1 | AG6: =COUNTIF(Tabla1[[#This Row],[GENERO_MASCULINO]:[GENERO_FEMENINO]],"FEMENINO") -> 1 | AH6: 40 | AI6: 14 | AJ6: 7 | AN6: 121 | AO6: =IFERROR(((VLOOKUP(Tabla1[[#This Row],[HIPOTESIS_1]],listas!$D$1:$E$105,2,FALSE))),"SIN INFORMACIÓN") -> No mantener distancia de seguridad. | AP6: 90 | AQ6: =IFERROR(((VLOOKUP(Tabla1[[#This Row],[HIPOTESIS_2]],listas!$D$1:$E$105,2,FALSE))),"") -> Transportar otra persona o cosas. | AR6: =IF(HOUR(Tabla1[[#This Row],[HORA_ACCIDENTE]])<6,"MAÑANA", IF(HOUR(Tabla1[[#This Row],[HORA_ACCIDENTE]])<12,"MAÑANA", IF(HOUR(Tabla1[[#This Row],[HORA_ACCIDENTE]])<18,"TARDE","NOCHE"))) -> TARDE
A7: 300 | B7: 0 | C7: 3 | D7: 0 | E7: =IF(D7>=1,"FALLECIDO",IF(C7>=1,"LESIONADO",IF(B7>=1,"SOLO DAÑO",""))) -> LESIONADO | F7: CARRERA 30 # 46 | G7: 5.3275139 | H7: -72.375592 | I7: MOVILIDAD | J7: URBANO | K7: =UPPER(TEXT(M7,"YYYY")) -> 2022 | L7: =UPPER(TEXT(M7,"MMMM")) -> SEPTIEMBRE | M7: 44810 | N7: =UPPER(TEXT(M7,"DDDD")) -> MARTES | O7: 0.9375 | P7: MOTOCICLETA | R7: =COUNTIF(Tabla1[[#This Row],[VEHICULOS_ACCIDENTADOS]:[VEHICULOS_ACCIDENTADOS2]],"MOTOCICLETA") -> 1 | S7: =COUNTIF(Tabla1[[#This Row],[VEHICULOS_ACCIDENTADOS]:[VEHICULOS_ACCIDENTADOS2]],"MOTOCARRO") -> 0 | T7: =COUNTIF(Tabla1[[#This Row],[VEHICULOS_ACCIDENTADOS]:[VEHICULOS_ACCIDENTADOS2]],"AUTOMOVIL") -> 0 | U7: =COUNTIF(Tabla1[[#This Row],[VEHICULOS_ACCIDENTADOS]:[VEHICULOS_ACCIDENTADOS2]],"CAMPERO") -> 0 | V7: =COUNTIF(Tabla1[[#This Row],[VEHICULOS_ACCIDENTADOS]:[VEHICULOS_ACCIDENTADOS2]],"CAMIONETA") -> 0 | W7: =COUNTIF(Tabla1[[#This Row],[VEHICULOS_ACCIDENTADOS]:[VEHICULOS_ACCIDENTADOS2]],"MICROBUS") -> 0 | X7: =COUNTIF(Tabla1[[#This Row],[VEHICULOS_ACCIDENTADOS]:[VEHICULOS_ACCIDENTADOS2]],"BUS") -> 0 | Y7: =COUNTIF(Tabla1[[#This Row],[VEHICULOS_ACCIDENTADOS]:[VEHICULOS_ACCIDENTADOS2]],"BUSETA") -> 0 | Z7: =COUNTIF(Tabla1[[#This Row],[VEHICULOS_ACCIDENTADOS]:[VEHICULOS_ACCIDENTADOS2]],"CAMION") -> 0 | AA7: =COUNTIF(Tabla1[[#This Row],[VEHICULOS_ACCIDENTADOS]:[VEHICULOS_ACCIDENTADOS2]],"TRACTOCAMION") -> 0 | AB7: =COUNTIF(Tabla1[[#This Row],[VEHICULOS_ACCIDENTADOS]:[VEHICULOS_ACCIDENTADOS2]],"VOLQUETA") -> 0 | AC7: =COUNTIF(Tabla1[[#This Row],[VEHICULOS_ACCIDENTADOS]:[VEHICULOS_ACCIDENTADOS2]],"BICICLETA") -> 0 | AD7: MASCULINO | AE7: FEMENINO | AF7: =COUNTIF(Tabla1[[#This Row],[GENERO_MASCULINO]:[GENERO_FEMENINO]],"MASCULINO") -> 1 | AG7: =COUNTIF(Tabla1[[#This Row],[GENERO_MASCULINO]:[GENERO_FEMENINO]],"FEMENINO") -> 1 | AH7: 24 | AI7: 24 | AL7: 30 | AN7: 139 | AO7: =IFERROR(((VLOOKUP(Tabla1[[#This Row],[HIPOTESIS_1]],listas!$D$1:$E$105,2,FALSE))),"SIN INFORMACIÓN") -> Impericia en el manejo. | AP7: 90 | AQ7: =IFERROR(((VLOOKUP(Tabla1[[#This Row],[HIPOTESIS_2]],listas!$D$1:$E$105,2,FALSE))),"") -> Transportar otra persona o cosas. | AR7: =IF(HOUR(Tabla1[[#This Row],[HORA_ACCIDENTE]])<6,"MAÑANA", IF(HOUR(Tabla1[[#This Row],[HORA_ACCIDENTE]])<12,"MAÑANA", IF(HOUR(Tabla1[[#This Row],[HORA_ACCIDENTE]])<18,"TARDE","NOCHE"))) -> NOCHE
A8: 750 | B8: 0 | C8: 1 | D8: 0 | E8: =IF(D8>=1,"FALLECIDO",IF(C8>=1,"LESIONADO",IF(B8>=1,"SOLO DAÑO",""))) -> LESIONADO | F8: CARRERA 5 ENTRE CALLE 39 Y 40 | G8: 5.3193556 | H8: -72.404717 | I8: MOVILIDAD | J8: URBANO | K8: =UPPER(TEXT(M8,"YYYY")) -> 2024 | L8: =UPPER(TEXT(M8,"MMMM")) -> JULIO | M8: 45498 | N8: =UPPER(TEXT(M8,"DDDD")) -> JUEVES | O8: 0.96180556 | P8: MOTOCICLETA | R8: =COUNTIF(Tabla1[[#This Row],[VEHICULOS_ACCIDENTADOS]:[VEHICULOS_ACCIDENTADOS2]],"MOTOCICLETA") -> 1 | S8: =COUNTIF(Tabla1[[#This Row],[VEHICULOS_ACCIDENTADOS]:[VEHICULOS_ACCIDENTADOS2]],"MOTOCARRO") -> 0 | T8: =COUNTIF(Tabla1[[#This Row],[VEHICULOS_ACCIDENTADOS]:[VEHICULOS_ACCIDENTADOS2]],"AUTOMOVIL") -> 0 | U8: =COUNTIF(Tabla1[[#This Row],[VEHICULOS_ACCIDENTADOS]:[VEHICULOS_ACCIDENTADOS2]],"CAMPERO") -> 0 | V8: =COUNTIF(Tabla1[[#This Row],[VEHICULOS_ACCIDENTADOS]:[VEHICULOS_ACCIDENTADOS2]],"CAMIONETA") -> 0 | W8: =COUNTIF(Tabla1[[#This Row],[VEHICULOS_ACCIDENTADOS]:[VEHICULOS_ACCIDENTADOS2]],"MICROBUS") -> 0 | X8: =COUNTIF(Tabla1[[#This Row],[VEHICULOS_ACCIDENTADOS]:[VEHICULOS_ACCIDENTADOS2]],"BUS") -> 0 | Y8: =COUNTIF(Tabla1[[#This Row],[VEHICULOS_ACCIDENTADOS]:[VEHICULOS_ACCIDENTADOS2]],"BUSETA") -> 0 | Z8: =COUNTIF(Tabla1[[#This Row],[VEHICULOS_ACCIDENTADOS]:[VEHICULOS_ACCIDENTADOS2]],"CAMION") -> 0 | AA8: =COUNTIF(Tabla1[[#This Row],[VEHICULOS_ACCIDENTADOS]:[VEHICULOS_ACCIDENTADOS2]],"TRACTOCAMION") -> 0 | AB8: =COUNTIF(Tabla1[[#This Row],[VEHICULOS_ACCIDENTADOS]:[VEHICULOS_ACCIDENTADOS2]],"VOLQUETA") -> 0 | AC8: =COUNTIF(Tabla1[[#This Row],[VEHICULOS_ACCIDENTADOS]:[VEHICULOS_ACCIDENTADOS2]],"BICICLETA") -> 0 | AD8: MASCULINO | AE8: FEMENINO | AF8: =COUNTIF(Tabla1[[#This Row],[GENERO_MASCULINO]:[GENERO_FEMENINO]],"MASCULINO") -> 1 | AG8: =COUNTIF(Tabla1[[#This Row],[GENERO_MASCULINO]:[GENERO_FEMENINO]],"FEMENINO") -> 1 | AH8: 26 | AI8: 65 | AN8: 115 | AO8: =IFERROR(((VLOOKUP(Tabla1[[#This Row],[HIPOTESIS_1]],listas!$D$1:$E$105,2,FALSE))),"SIN INFORMACIÓN") -> Embriaguez o Sustancias alucinogenas | AP8: 404 | AQ8: =IFERROR(((VLOOKUP(Tabla1[[#This Row],[HIPOTESIS_2]],listas!$D$1:$E$105,2,FALSE))),"") -> Transitar por la calzada. | AR8: =IF(HOUR(Tabla1[[#This Row],[HORA_ACCIDENTE]])<6,"MAÑANA", IF(HOUR(Tabla1[[#This Row],[HORA_ACCIDENTE]])<12,"MAÑANA", IF(HOUR(Tabla1[[#This Row],[HORA_ACCIDENTE]])<18,"TARDE","NOCHE"))) -> NOCHE
A9: 185 | B9: 0 | C9: 2 | D9: 0 | E9: =IF(D9>=1,"FALLECIDO",IF(C9>=1,"LESIONADO",IF(B9>=1,"SOLO DAÑO",""))) -> LESIONADO | F9: KM. 0+500 YOPAL PAZ DE ARIPORO | G9: 5.3553228 | H9: -72.406182 | I9: MOVILIDAD | J9: RURAL | K9: =UPPER(TEXT(M9,"YYYY")) -> 2022 | L9: =UPPER(TEXT(M9,"MMMM")) -> MAYO | M9: 44696 | N9: =UPPER(TEXT(M9,"DDDD")) -> DOMINGO | O9: 0.90625 | P9: MOTOCICLETA | R9: =COUNTIF(Tabla1[[#This Row],[VEHICULOS_ACCIDENTADOS]:[VEHICULOS_ACCIDENTADOS2]],"MOTOCICLETA") -> 1 | S9: =COUNTIF(Tabla1[[#This Row],[VEHICULOS_ACCIDENTADOS]:[VEHICULOS_ACCIDENTADOS2]],"MOTOCARRO") -> 0 | T9: =COUNTIF(Tabla1[[#This Row],[VEHICULOS_ACCIDENTADOS]:[VEHICULOS_ACCIDENTADOS2]],"AUTOMOVIL") -> 0 | U9: =COUNTIF(Tabla1[[#This Row],[VEHICULOS_ACCIDENTADOS]:[VEHICULOS_ACCIDENTADOS2]],"CAMPERO") -> 0 | V9: =COUNTIF(Tabla1[[#This Row],[VEHICULOS_ACCIDENTADOS]:[VEHICULOS_ACCIDENTADOS2]],"CAMIONETA") -> 0 | W9: =COUNTIF(Tabla1[[#This Row],[VEHICULOS_ACCIDENTADOS]:[VEHICULOS_ACCIDENTADOS2]],"MICROBUS") -> 0 | X9: =COUNTIF(Tabla1[[#This Row],[VEHICULOS_ACCIDENTADOS]:[VEHICULOS_ACCIDENTADOS2]],"BUS") -> 0 | Y9: =COUNTIF(Tabla1[[#This Row],[VEHICULOS_ACCIDENTADOS]:[VEHICULOS_ACCIDENTADOS2]],"BUSETA") -> 0 | Z9: =COUNTIF(Tabla1[[#This Row],[VEHICULOS_ACCIDENTADOS]:[VEHICULOS_ACCIDENTADOS2]],"CAMION") -> 0 | AA9: =COUNTIF(Tabla1[[#This Row],[VEHICULOS_ACCIDENTADOS]:[VEHICULOS_ACCIDENTADOS2]],"TRACTOCAMION") -> 0 | AB9: =COUNTIF(Tabla1[[#This Row],[VEHICULOS_ACCIDENTADOS]:[VEHICULOS_ACCIDENTADOS2]],"VOLQUETA") -> 0 | AC9: =COUNTIF(Tabla1[[#This Row],[VEHICULOS_ACCIDENTADOS]:[VEHICULOS_ACCIDENTADOS2]],"BICICLETA") -> 0 | AD9: MASCULINO | AF9: =COUNTIF(Tabla1[[#This Row],[GENERO_MASCULINO]:[GENERO_FEMENINO]],"MASCULINO") -> 1 | AG9: =COUNTIF(Tabla1[[#This Row],[GENERO_MASCULINO]:[GENERO_FEMENINO]],"FEMENINO") -> 0 | AH9: 28 | AK9: 75 | AN9: 157 | AO9: =IFERROR(((VLOOKUP(Tabla1[[#This Row],[HIPOTESIS_1]],listas!$D$1:$E$105,2,FALSE))),"SIN INFORMACIÓN") -> Otra | AP9: 404 | AQ9: =IFERROR(((VLOOKUP(Tabla1[[#This Row],[HIPOTESIS_2]],listas!$D$1:$E$105,2,FALSE))),"") -> Transitar por la calzada. | AR9: =IF(HOUR(Tabla1[[#This Row],[HORA_ACCIDENTE]])<6,"MAÑANA", IF(HOUR(Tabla1[[#This Row],[HORA_ACCIDENTE]])<12,"MAÑANA", IF(HOUR(Tabla1[[#This Row],[HORA_ACCIDENTE]])<18,"TARDE","NOCHE"))) -> NOCHE
A10: 1116 | B10: 0 | C10: 3 | D10: 0 | E10: =IF(D10>=1,"FALLECIDO",IF(C10>=1,"LESIONADO",IF(B10>=1,"SOLO DAÑO",""))) -> LESIONADO | F10: CARRERA 12 # CALLE 27 | G10: 5.3295167 | H10: -72.400506 | I10: MOVILIDAD | J10: URBANO | K10: =UPPER(TEXT(M10,"YYYY")) -> 2025 | L10: =UPPER(TEXT(M10,"MMMM")) -> OCTUBRE | M10: 45935 | N10: =UPPER(TEXT(M10,"DDDD")) -> DOMINGO | O10: 0.80486111 | P10: MOTOCICLETA | Q10: MOTOCICLETA | R10: =COUNTIF(Tabla1[[#This Row],[VEHICULOS_ACCIDENTADOS]:[VEHICULOS_ACCIDENTADOS2]],"MOTOCICLETA") -> 2 | S10: =COUNTIF(Tabla1[[#This Row],[VEHICULOS_ACCIDENTADOS]:[VEHICULOS_ACCIDENTADOS2]],"MOTOCARRO") -> 0 | T10: =COUNTIF(Tabla1[[#This Row],[VEHICULOS_ACCIDENTADOS]:[VEHICULOS_ACCIDENTADOS2]],"AUTOMOVIL") -> 0 | U10: =COUNTIF(Tabla1[[#This Row],[VEHICULOS_ACCIDENTADOS]:[VEHICULOS_ACCIDENTADOS2]],"CAMPERO") -> 0 | V10: =COUNTIF(Tabla1[[#This Row],[VEHICULOS_ACCIDENTADOS]:[VEHICULOS_ACCIDENTADOS2]],"CAMIONETA") -> 0 | W10: =COUNTIF(Tabla1[[#This Row],[VEHICULOS_ACCIDENTADOS]:[VEHICULOS_ACCIDENTADOS2]],"MICROBUS") -> 0 | X10: =COUNTIF(Tabla1[[#This Row],[VEHICULOS_ACCIDENTADOS]:[VEHICULOS_ACCIDENTADOS2]],"BUS") -> 0 | Y10: =COUNTIF(Tabla1[[#This Row],[VEHICULOS_ACCIDENTADOS]:[VEHICULOS_ACCIDENTADOS2]],"BUSETA") -> 0 | Z10: =COUNTIF(Tabla1[[#This Row],[VEHICULOS_ACCIDENTADOS]:[VEHICULOS_ACCIDENTADOS2]],"CAMION") -> 0 | AA10: =COUNTIF(Tabla1[[#This Row],[VEHICULOS_ACCIDENTADOS]:[VEHICULOS_ACCIDENTADOS2]],"TRACTOCAMION") -> 0 | AB10: =COUNTIF(Tabla1[[#This Row],[VEHICULOS_ACCIDENTADOS]:[VEHICULOS_ACCIDENTADOS2]],"VOLQUETA") -> 0 | AC10: =COUNTIF(Tabla1[[#This Row],[VEHICULOS_ACCIDENTADOS]:[VEHICULOS_ACCIDENTADOS2]],"BICICLETA") -> 0 | AD10: MASCULINO | AE10: FEMENINO | AF10: =COUNTIF(Tabla1[[#This Row],[GENERO_MASCULINO]:[GENERO_FEMENINO]],"MASCULINO") -> 1 | AG10: =COUNTIF(Tabla1[[#This Row],[GENERO_MASCULINO]:[GENERO_FEMENINO]],"FEMENINO") -> 1 | AH10: 35 | AI10: 36 | AN10: 115 | AO10: =IFERROR(((VLOOKUP(Tabla1[[#This Row],[HIPOTESIS_1]],listas!$D$1:$E$105,2,FALSE))),"SIN INFORMACIÓN") -> Embriaguez o Sustancias alucinogenas | AP10: 127 | AQ10: =IFERROR(((VLOOKUP(Tabla1[[#This Row],[HIPOTESIS_2]],listas!$D$1:$E$105,2,FALSE))),"") -> Transitar en contravía. | AR10: =IF(HOUR(Tabla1[[#This Row],[HORA_ACCIDENTE]])<6,"MAÑANA", IF(HOUR(Tabla1[[#This Row],[HORA_ACCIDENTE]])<12,"MAÑANA", IF(HOUR(Tabla1[[#This Row],[HORA_ACCIDENTE]])<18,"TARDE","NOCHE"))) -> NOCHE
A11: 682 | B11: 0 | C11: 2 | D11: 0 | E11: =IF(D11>=1,"FALLECIDO",IF(C11>=1,"LESIONADO",IF(B11>=1,"SOLO DAÑO",""))) -> LESIONADO | F11: CARRERA 13 DIAGONAL 47 | G11: 5.3130556 | H11: -72.395925 | I11: MOVILIDAD | J11: URBANO | K11: =UPPER(TEXT(M11,"YYYY")) -> 2024 | L11: =UPPER(TEXT(M11,"MMMM")) -> MARZO | M11: 45373 | N11: =UPPER(TEXT(M11,"DDDD")) -> VIERNES | O11: 0.75 | P11: MOTOCICLETA | Q11: MOTOCICLETA | R11: =COUNTIF(Tabla1[[#This Row],[VEHICULOS_ACCIDENTADOS]:[VEHICULOS_ACCIDENTADOS2]],"MOTOCICLETA") -> 2 | S11: =COUNTIF(Tabla1[[#This Row],[VEHICULOS_ACCIDENTADOS]:[VEHICULOS_ACCIDENTADOS2]],"MOTOCARRO") -> 0 | T11: =COUNTIF(Tabla1[[#This Row],[VEHICULOS_ACCIDENTADOS]:[VEHICULOS_ACCIDENTADOS2]],"AUTOMOVIL") -> 0 | U11: =COUNTIF(Tabla1[[#This Row],[VEHICULOS_ACCIDENTADOS]:[VEHICULOS_ACCIDENTADOS2]],"CAMPERO") -> 0 | V11: =COUNTIF(Tabla1[[#This Row],[VEHICULOS_ACCIDENTADOS]:[VEHICULOS_ACCIDENTADOS2]],"CAMIONETA") -> 0 | W11: =COUNTIF(Tabla1[[#This Row],[VEHICULOS_ACCIDENTADOS]:[VEHICULOS_ACCIDENTADOS2]],"MICROBUS") -> 0 | X11: =COUNTIF(Tabla1[[#This Row],[VEHICULOS_ACCIDENTADOS]:[VEHICULOS_ACCIDENTADOS2]],"BUS") -> 0 | Y11: =COUNTIF(Tabla1[[#This Row],[VEHICULOS_ACCIDENTADOS]:[VEHICULOS_ACCIDENTADOS2]],"BUSETA") -> 0 | Z11: =COUNTIF(Tabla1[[#This Row],[VEHICULOS_ACCIDENTADOS]:[VEHICULOS_ACCIDENTADOS2]],"CAMION") -> 0 | AA11: =COUNTIF(Tabla1[[#This Row],[VEHICULOS_ACCIDENTADOS]:[VEHICULOS_ACCIDENTADOS2]],"TRACTOCAMION") -> 0 | AB11: =COUNTIF(Tabla1[[#This Row],[VEHICULOS_ACCIDENTADOS]:[VEHICULOS_ACCIDENTADOS2]],"VOLQUETA") -> 0 | AC11: =COUNTIF(Tabla1[[#This Row],[VEHICULOS_ACCIDENTADOS]:[VEHICULOS_ACCIDENTADOS2]],"BICICLETA") -> 0 | AD11: MASCULINO | AE11: FEMENINO | AF11: =COUNTIF(Tabla1[[#This Row],[GENERO_MASCULINO]:[GENERO_FEMENINO]],"MASCULINO") -> 1 | AG11: =COUNTIF(Tabla1[[#This Row],[GENERO_MASCULINO]:[GENERO_FEMENINO]],"FEMENINO") -> 1 | AH11: 46 | AI11: 0 | AK11: 0 | AN11: 115 | AO11: =IFERROR(((VLOOKUP(Tabla1[[#This Row],[HIPOTESIS_1]],listas!$D$1:$E$105,2,FALSE))),"SIN INFORMACIÓN") -> Embriaguez o Sustancias alucinogenas | AP11: 127 | AQ11: =IFERROR(((VLOOKUP(Tabla1[[#This Row],[HIPOTESIS_2]],listas!$D$1:$E$105,2,FALSE))),"") -> Transitar en contravía. | AR11: =IF(HOUR(Tabla1[[#This Row],[HORA_ACCIDENTE]])<6,"MAÑANA", IF(HOUR(Tabla1[[#This Row],[HORA_ACCIDENTE]])<12,"MAÑANA", IF(HOUR(Tabla1[[#This Row],[HORA_ACCIDENTE]])<18,"TARDE","NOCHE"))) -> NOCHE
A12: 1072 | B12: 0 | C12: 0 | D12: 1 | E12: =IF(D12>=1,"FALLECIDO",IF(C12>=1,"LESIONADO",IF(B12>=1,"SOLO DAÑO",""))) -> FALLECIDO | F12: CARRERA 16 # CALLE 40 | G12: 5.3191117 | H12: -72.393685 | I12: MOVILIDAD | J12: URBANO | K12: =UPPER(TEXT(M12,"YYYY")) -> 2025 | L12: =UPPER(TEXT(M12,"MMMM")) -> SEPTIEMBRE | M12: 45914 | N12: =UPPER(TEXT(M12,"DDDD")) -> DOMINGO | O12: 0.20138889 | P12: MOTOCICLETA | R12: =COUNTIF(Tabla1[[#This Row],[VEHICULOS_ACCIDENTADOS]:[VEHICULOS_ACCIDENTADOS2]],"MOTOCICLETA") -> 1 | S12: =COUNTIF(Tabla1[[#This Row],[VEHICULOS_ACCIDENTADOS]:[VEHICULOS_ACCIDENTADOS2]],"MOTOCARRO") -> 0 | T12: =COUNTIF(Tabla1[[#This Row],[VEHICULOS_ACCIDENTADOS]:[VEHICULOS_ACCIDENTADOS2]],"AUTOMOVIL") -> 0 | U12: =COUNTIF(Tabla1[[#This Row],[VEHICULOS_ACCIDENTADOS]:[VEHICULOS_ACCIDENTADOS2]],"CAMPERO") -> 0 | V12: =COUNTIF(Tabla1[[#This Row],[VEHICULOS_ACCIDENTADOS]:[VEHICULOS_ACCIDENTADOS2]],"CAMIONETA") -> 0 | W12: =COUNTIF(Tabla1[[#This Row],[VEHICULOS_ACCIDENTADOS]:[VEHICULOS_ACCIDENTADOS2]],"MICROBUS") -> 0 | X12: =COUNTIF(Tabla1[[#This Row],[VEHICULOS_ACCIDENTADOS]:[VEHICULOS_ACCIDENTADOS2]],"BUS") -> 0 | Y12: =COUNTIF(Tabla1[[#This Row],[VEHICULOS_ACCIDENTADOS]:[VEHICULOS_ACCIDENTADOS2]],"BUSETA") -> 0 | Z12: =COUNTIF(Tabla1[[#This Row],[VEHICULOS_ACCIDENTADOS]:[VEHICULOS_ACCIDENTADOS2]],"CAMION") -> 0 | AA12: =COUNTIF(Tabla1[[#This Row],[VEHICULOS_ACCIDENTADOS]:[VEHICULOS_ACCIDENTADOS2]],"TRACTOCAMION") -> 0 | AB12: =COUNTIF(Tabla1[[#This Row],[VEHICULOS_ACCIDENTADOS]:[VEHICULOS_ACCIDENTADOS2]],"VOLQUETA") -> 0 | AC12: =COUNTIF(Tabla1[[#This Row],[VEHICULOS_ACCIDENTADOS]:[VEHICULOS_ACCIDENTADOS2]],"BICICLETA") -> 0 | AD12: MASCULINO | AF12: =COUNTIF(Tabla1[[#This Row],[GENERO_MASCULINO]:[GENERO_FEMENINO]],"MASCULINO") -> 1 | AG12: =COUNTIF(Tabla1[[#This Row],[GENERO_MASCULINO]:[GENERO_FEMENINO]],"FEMENINO") -> 0 | AH12: 30 | AN12: 114 | AO12: =IFERROR(((VLOOKUP(Tabla1[[#This Row],[HIPOTESIS_1]],listas!$D$1:$E$105,2,FALSE))),"SIN INFORMACIÓN") -> Embriaguez aparente. | AP12: 127 | AQ12: =IFERROR(((VLOOKUP(Tabla1[[#This Row],[HIPOTESIS_2]],listas!$D$1:$E$105,2,FALSE))),"") -> Transitar en contravía. | AR12: =IF(HOUR(Tabla1[[#This Row],[HORA_ACCIDENTE]])<6,"MAÑANA", IF(HOUR(Tabla1[[#This Row],[HORA_ACCIDENTE]])<12,"MAÑANA", IF(HOUR(Tabla1[[#This Row],[HORA_ACCIDENTE]])<18,"TARDE","NOCHE"))) -> MAÑANA
A13: 897 | B13: 1 | C13: 0 | D13: 0 | E13: =IF(D13>=1,"FALLECIDO",IF(C13>=1,"LESIONADO",IF(B13>=1,"SOLO DAÑO",""))) -> SOLO DAÑO | F13: CARRERA 19 # 20-69 | G13: 5.33943 | H13: -72.397135 | I13: MOVILIDAD | J13: URBANO | K13: =UPPER(TEXT(M13,"YYYY")) -> 2025 | L13: =UPPER(TEXT(M13,"MMMM")) -> MARZO | M13: 45724 | N13: =UPPER(TEXT(M13,"DDDD")) -> SÁBADO | O13: 0.97916667 | P13: MOTOCICLETA | R13: =COUNTIF(Tabla1[[#This Row],[VEHICULOS_ACCIDENTADOS]:[VEHICULOS_ACCIDENTADOS2]],"MOTOCICLETA") -> 1 | S13: =COUNTIF(Tabla1[[#This Row],[VEHICULOS_ACCIDENTADOS]:[VEHICULOS_ACCIDENTADOS2]],"MOTOCARRO") -> 0 | T13: =COUNTIF(Tabla1[[#This Row],[VEHICULOS_ACCIDENTADOS]:[VEHICULOS_ACCIDENTADOS2]],"AUTOMOVIL") -> 0 | U13: =COUNTIF(Tabla1[[#This Row],[VEHICULOS_ACCIDENTADOS]:[VEHICULOS_ACCIDENTADOS2]],"CAMPERO") -> 0 | V13: =COUNTIF(Tabla1[[#This Row],[VEHICULOS_ACCIDENTADOS]:[VEHICULOS_ACCIDENTADOS2]],"CAMIONETA") -> 0 | W13: =COUNTIF(Tabla1[[#This Row],[VEHICULOS_ACCIDENTADOS]:[VEHICULOS_ACCIDENTADOS2]],"MICROBUS") -> 0 | X13: =COUNTIF(Tabla1[[#This Row],[VEHICULOS_ACCIDENTADOS]:[VEHICULOS_ACCIDENTADOS2]],"BUS") -> 0 | Y13: =COUNTIF(Tabla1[[#This Row],[VEHICULOS_ACCIDENTADOS]:[VEHICULOS_ACCIDENTADOS2]],"BUSETA") -> 0 | Z13: =COUNTIF(Tabla1[[#This Row],[VEHICULOS_ACCIDENTADOS]:[VEHICULOS_ACCIDENTADOS2]],"CAMION") -> 0 | AA13: =COUNTIF(Tabla1[[#This Row],[VEHICULOS_ACCIDENTADOS]:[VEHICULOS_ACCIDENTADOS2]],"TRACTOCAMION") -> 0 | AB13: =COUNTIF(Tabla1[[#This Row],[VEHICULOS_ACCIDENTADOS]:[VEHICULOS_ACCIDENTADOS2]],"VOLQUETA") -> 0 | AC13: =COUNTIF(Tabla1[[#This Row],[VEHICULOS_ACCIDENTADOS]:[VEHICULOS_ACCIDENTADOS2]],"BICICLETA") -> 0 | AD13: MASCULINO | AE13: MASCULINO | AF13: =COUNTIF(Tabla1[[#This Row],[GENERO_MASCULINO]:[GENERO_FEMENINO]],"MASCULINO") -> 2 | AG13: =COUNTIF(Tabla1[[#This Row],[GENERO_MASCULINO]:[GENERO_FEMENINO]],"FEMENINO") -> 0 | AH13: 35 | AI13: 35 | AN13: 115 | AO13: =IFERROR(((VLOOKUP(Tabla1[[#This Row],[HIPOTESIS_1]],listas!$D$1:$E$105,2,FALSE))),"SIN INFORMACIÓN") -> Embriaguez o Sustancias alucinogenas | AP13: 127 | AQ13: =IFERROR(((VLOOKUP(Tabla1[[#This Row],[HIPOTESIS_2]],listas!$D$1:$E$105,2,FALSE))),"") -> Transitar en contravía. | AR13: =IF(HOUR(Tabla1[[#This Row],[HORA_ACCIDENTE]])<6,"MAÑANA", IF(HOUR(Tabla1[[#This Row],[HORA_ACCIDENTE]])<12,"MAÑANA", IF(HOUR(Tabla1[[#This Row],[HORA_ACCIDENTE]])<18,"TARDE","NOCHE"))) -> NOCHE
A14: 328 | B14: 0 | C14: 0 | D14: 1 | E14: =IF(D14>=1,"FALLECIDO",IF(C14>=1,"LESIONADO",IF(B14>=1,"SOLO DAÑO",""))) -> FALLECIDO | F14: CARRERA 21 # 7-67 | G14: 5.3495778 | H14: -72.4004 | I14: MOVILIDAD | J14: URBANO | K14: =UPPER(TEXT(M14,"YYYY")) -> 2022 | L14: =UPPER(TEXT(M14,"MMMM")) -> OCTUBRE | M14: 44843 | N14: =UPPER(TEXT(M14,"DDDD")) -> DOMINGO | O14: 0.20486111 | P14: MOTOCICLETA | R14: =COUNTIF(Tabla1[[#This Row],[VEHICULOS_ACCIDENTADOS]:[VEHICULOS_ACCIDENTADOS2]],"MOTOCICLETA") -> 1 | S14: =COUNTIF(Tabla1[[#This Row],[VEHICULOS_ACCIDENTADOS]:[VEHICULOS_ACCIDENTADOS2]],"MOTOCARRO") -> 0 | T14: =COUNTIF(Tabla1[[#This Row],[VEHICULOS_ACCIDENTADOS]:[VEHICULOS_ACCIDENTADOS2]],"AUTOMOVIL") -> 0 | U14: =COUNTIF(Tabla1[[#This Row],[VEHICULOS_ACCIDENTADOS]:[VEHICULOS_ACCIDENTADOS2]],"CAMPERO") -> 0 | V14: =COUNTIF(Tabla1[[#This Row],[VEHICULOS_ACCIDENTADOS]:[VEHICULOS_ACCIDENTADOS2]],"CAMIONETA") -> 0 | W14: =COUNTIF(Tabla1[[#This Row],[VEHICULOS_ACCIDENTADOS]:[VEHICULOS_ACCIDENTADOS2]],"MICROBUS") -> 0 | X14: =COUNTIF(Tabla1[[#This Row],[VEHICULOS_ACCIDENTADOS]:[VEHICULOS_ACCIDENTADOS2]],"BUS") -> 0 | Y14: =COUNTIF(Tabla1[[#This Row],[VEHICULOS_ACCIDENTADOS]:[VEHICULOS_ACCIDENTADOS2]],"BUSETA") -> 0 | Z14: =COUNTIF(Tabla1[[#This Row],[VEHICULOS_ACCIDENTADOS]:[VEHICULOS_ACCIDENTADOS2]],"CAMION") -> 0 | AA14: =COUNTIF(Tabla1[[#This Row],[VEHICULOS_ACCIDENTADOS]:[VEHICULOS_ACCIDENTADOS2]],"TRACTOCAMION") -> 0 | AB14: =COUNTIF(Tabla1[[#This Row],[VEHICULOS_ACCIDENTADOS]:[VEHICULOS_ACCIDENTADOS2]],"VOLQUETA") -> 0 | AC14: =COUNTIF(Tabla1[[#This Row],[VEHICULOS_ACCIDENTADOS]:[VEHICULOS_ACCIDENTADOS2]],"BICICLETA") -> 0 | AE14: FEMENINO | AF14: =COUNTIF(Tabla1[[#This Row],[GENERO_MASCULINO]:[GENERO_FEMENINO]],"MASCULINO") -> 0 | AG14: =COUNTIF(Tabla1[[#This Row],[GENERO_MASCULINO]:[GENERO_FEMENINO]],"FEMENINO") -> 1 | AM14: 20 | AN14: 114 | AO14: =IFERROR(((VLOOKUP(Tabla1[[#This Row],[HIPOTESIS_1]],listas!$D$1:$E$105,2,FALSE))),"SIN INFORMACIÓN") -> Embriaguez aparente. | AP14: 127 | AQ14: =IFERROR(((VLOOKUP(Tabla1[[#This Row],[HIPOTESIS_2]],listas!$D$1:$E$105,2,FALSE))),"") -> Transitar en contravía. | AR14: =IF(HOUR(Tabla1[[#This Row],[HORA_ACCIDENTE]])<6,"MAÑANA", IF(HOUR(Tabla1[[#This Row],[HORA_ACCIDENTE]])<12,"MAÑANA", IF(HOUR(Tabla1[[#This Row],[HORA_ACCIDENTE]])<18,"TARDE","NOCHE"))) -> MAÑANA
A15: 853 | B15: 1 | C15: 0 | D15: 0 | E15: =IF(D15>=1,"FALLECIDO",IF(C15>=1,"LESIONADO",IF(B15>=1,"SOLO DAÑO",""))) -> SOLO DAÑO | F15: CARRERA 22 # 15 | G15: 5.3439278 | H15: -72.395764 | I15: MOVILIDAD | J15: URBANO | K15: =UPPER(TEXT(M15,"YYYY")) -> 2025 | L15: =UPPER(TEXT(M15,"MMMM")) -> ENERO | M15: 45660 | N15: =UPPER(TEXT(M15,"DDDD")) -> VIERNES | O15: 0.73958333 | P15: MOTOCICLETA | Q15: MOTOCICLETA | R15: =COUNTIF(Tabla1[[#This Row],[VEHICULOS_ACCIDENTADOS]:[VEHICULOS_ACCIDENTADOS2]],"MOTOCICLETA") -> 2 | S15: =COUNTIF(Tabla1[[#This Row],[VEHICULOS_ACCIDENTADOS]:[VEHICULOS_ACCIDENTADOS2]],"MOTOCARRO") -> 0 | T15: =COUNTIF(Tabla1[[#This Row],[VEHICULOS_ACCIDENTADOS]:[VEHICULOS_ACCIDENTADOS2]],"AUTOMOVIL") -> 0 | U15: =COUNTIF(Tabla1[[#This Row],[VEHICULOS_ACCIDENTADOS]:[VEHICULOS_ACCIDENTADOS2]],"CAMPERO") -> 0 | V15: =COUNTIF(Tabla1[[#This Row],[VEHICULOS_ACCIDENTADOS]:[VEHICULOS_ACCIDENTADOS2]],"CAMIONETA") -> 0 | W15: =COUNTIF(Tabla1[[#This Row],[VEHICULOS_ACCIDENTADOS]:[VEHICULOS_ACCIDENTADOS2]],"MICROBUS") -> 0 | X15: =COUNTIF(Tabla1[[#This Row],[VEHICULOS_ACCIDENTADOS]:[VEHICULOS_ACCIDENTADOS2]],"BUS") -> 0 | Y15: =COUNTIF(Tabla1[[#This Row],[VEHICULOS_ACCIDENTADOS]:[VEHICULOS_ACCIDENTADOS2]],"BUSETA") -> 0 | Z15: =COUNTIF(Tabla1[[#This Row],[VEHICULOS_ACCIDENTADOS]:[VEHICULOS_ACCIDENTADOS2]],"CAMION") -> 0 | AA15: =COUNTIF(Tabla1[[#This Row],[VEHICULOS_ACCIDENTADOS]:[VEHICULOS_ACCIDENTADOS2]],"TRACTOCAMION") -> 0 | AB15: =COUNTIF(Tabla1[[#This Row],[VEHICULOS_ACCIDENTADOS]:[VEHICULOS_ACCIDENTADOS2]],"VOLQUETA") -> 0 | AC15: =COUNTIF(Tabla1[[#This Row],[VEHICULOS_ACCIDENTADOS]:[VEHICULOS_ACCIDENTADOS2]],"BICICLETA") -> 0 | AD15: MASCULINO | AE15: MASCULINO | AF15: =COUNTIF(Tabla1[[#This Row],[GENERO_MASCULINO]:[GENERO_FEMENINO]],"MASCULINO") -> 2 | AG15: =COUNTIF(Tabla1[[#This Row],[GENERO_MASCULINO]:[GENERO_FEMENINO]],"FEMENINO") -> 0 | AH15: 19 | AI15: 64 | AN15: 115 | AO15: =IFERROR(((VLOOKUP(Tabla1[[#This Row],[HIPOTESIS_1]],listas!$D$1:$E$105,2,FALSE))),"SIN INFORMACIÓN") -> Embriaguez o Sustancias alucinogenas | AP15: 127 | AQ15: =IFERROR(((VLOOKUP(Tabla1[[#This Row],[HIPOTESIS_2]],listas!$D$1:$E$105,2,FALSE))),"") -> Transitar en contravía. | AR15: =IF(HOUR(Tabla1[[#This Row],[HORA_ACCIDENTE]])<6,"MAÑANA", IF(HOUR(Tabla1[[#This Row],[HORA_ACCIDENTE]])<12,"MAÑANA", IF(HOUR(Tabla1[[#This Row],[HORA_ACCIDENTE]])<18,"TARDE","NOCHE"))) -> TARDE
A16: 369 | B16: 0 | C16: 2 | D16: 0 | E16: =IF(D16>=1,"FALLECIDO",IF(C16>=1,"LESIONADO",IF(B16>=1,"SOLO DAÑO",""))) -> LESIONADO | F16: CARRERA 23 # 17 | G16: 5.3427833 | H16: -72.394019 | I16: MOVILIDAD | J16: URBANO | K16: =UPPER(TEXT(M16,"YYYY")) -> 2022 | L16: =UPPER(TEXT(M16,"MMMM")) -> DICIEMBRE | M16: 44902 | N16: =UPPER(TEXT(M16,"DDDD")) -> MIÉRCOLES | O16: 0.72916667 | P16: MOTOCICLETA | Q16: CAMIONETA | R16: =COUNTIF(Tabla1[[#This Row],[VEHICULOS_ACCIDENTADOS]:[VEHICULOS_ACCIDENTADOS2]],"MOTOCICLETA") -> 1 | S16: =COUNTIF(Tabla1[[#This Row],[VEHICULOS_ACCIDENTADOS]:[VEHICULOS_ACCIDENTADOS2]],"MOTOCARRO") -> 0 | T16: =COUNTIF(Tabla1[[#This Row],[VEHICULOS_ACCIDENTADOS]:[VEHICULOS_ACCIDENTADOS2]],"AUTOMOVIL") -> 0 | U16: =COUNTIF(Tabla1[[#This Row],[VEHICULOS_ACCIDENTADOS]:[VEHICULOS_ACCIDENTADOS2]],"CAMPERO") -> 0 | V16: =COUNTIF(Tabla1[[#This Row],[VEHICULOS_ACCIDENTADOS]:[VEHICULOS_ACCIDENTADOS2]],"CAMIONETA") -> 1 | W16: =COUNTIF(Tabla1[[#This Row],[VEHICULOS_ACCIDENTADOS]:[VEHICULOS_ACCIDENTADOS2]],"MICROBUS") -> 0 | X16: =COUNTIF(Tabla1[[#This Row],[VEHICULOS_ACCIDENTADOS]:[VEHICULOS_ACCIDENTADOS2]],"BUS") -> 0 | Y16: =COUNTIF(Tabla1[[#This Row],[VEHICULOS_ACCIDENTADOS]:[VEHICULOS_ACCIDENTADOS2]],"BUSETA") -> 0 | Z16: =COUNTIF(Tabla1[[#This Row],[VEHICULOS_ACCIDENTADOS]:[VEHICULOS_ACCIDENTADOS2]],"CAMION") -> 0 | AA16: =COUNTIF(Tabla1[[#This Row],[VEHICULOS_ACCIDENTADOS]:[VEHICULOS_ACCIDENTADOS2]],"TRACTOCAMION") -> 0 | AB16: =COUNTIF(Tabla1[[#This Row],[VEHICULOS_ACCIDENTADOS]:[VEHICULOS_ACCIDENTADOS2]],"VOLQUETA") -> 0 | AC16: =COUNTIF(Tabla1[[#This Row],[VEHICULOS_ACCIDENTADOS]:[VEHICULOS_ACCIDENTADOS2]],"BICICLETA") -> 0 | AE16: FEMENINO | AF16: =COUNTIF(Tabla1[[#This Row],[GENERO_MASCULINO]:[GENERO_FEMENINO]],"MASCULINO") -> 0 | AG16: =COUNTIF(Tabla1[[#This Row],[GENERO_MASCULINO]:[GENERO_FEMENINO]],"FEMENINO") -> 1 | AH16: 32 | AL16: 12 | AN16: 112 | AO16: =IFERROR(((VLOOKUP(Tabla1[[#This Row],[HIPOTESIS_1]],listas!$D$1:$E$105,2,FALSE))),"SIN INFORMACIÓN") -> Desobedecer señales o normas de tránsito. | AP16: 127 | AQ16: =IFERROR(((VLOOKUP(Tabla1[[#This Row],[HIPOTESIS_2]],listas!$D$1:$E$105,2,FALSE))),"") -> Transitar en contravía. | AR16: =IF(HOUR(Tabla1[[#This Row],[HORA_ACCIDENTE]])<6,"MAÑANA", IF(HOUR(Tabla1[[#This Row],[HORA_ACCIDENTE]])<12,"MAÑANA", IF(HOUR(Tabla1[[#This Row],[HORA_ACCIDENTE]])<18,"TARDE","NOCHE"))) -> TARDE
A17: 834 | B17: 1 | C17: 0 | D17: 0 | E17: =IF(D17>=1,"FALLECIDO",IF(C17>=1,"LESIONADO",IF(B17>=1,"SOLO DAÑO",""))) -> SOLO DAÑO | F17: CARRERA 23 CALLE 39 | G17: 5.3251547 | H17: -72.384342 | I17: MOVILIDAD | J17: URBANO | K17: =UPPER(TEXT(M17,"YYYY")) -> 2024 | L17: =UPPER(TEXT(M17,"MMMM")) -> DICIEMBRE | M17: 45640 | N17: =UPPER(TEXT(M17,"DDDD")) -> SÁBADO | O17: 0.79166667 | P17: MOTOCICLETA | Q17: BICICLETA | R17: =COUNTIF(Tabla1[[#This Row],[VEHICULOS_ACCIDENTADOS]:[VEHICULOS_ACCIDENTADOS2]],"MOTOCICLETA") -> 1 | S17: =COUNTIF(Tabla1[[#This Row],[VEHICULOS_ACCIDENTADOS]:[VEHICULOS_ACCIDENTADOS2]],"MOTOCARRO") -> 0 | T17: =COUNTIF(Tabla1[[#This Row],[VEHICULOS_ACCIDENTADOS]:[VEHICULOS_ACCIDENTADOS2]],"AUTOMOVIL") -> 0 | U17: =COUNTIF(Tabla1[[#This Row],[VEHICULOS_ACCIDENTADOS]:[VEHICULOS_ACCIDENTADOS2]],"CAMPERO") -> 0 | V17: =COUNTIF(Tabla1[[#This Row],[VEHICULOS_ACCIDENTADOS]:[VEHICULOS_ACCIDENTADOS2]],"CAMIONETA") -> 0 | W17: =COUNTIF(Tabla1[[#This Row],[VEHICULOS_ACCIDENTADOS]:[VEHICULOS_ACCIDENTADOS2]],"MICROBUS") -> 0 | X17: =COUNTIF(Tabla1[[#This Row],[VEHICULOS_ACCIDENTADOS]:[VEHICULOS_ACCIDENTADOS2]],"BUS") -> 0 | Y17: =COUNTIF(Tabla1[[#This Row],[VEHICULOS_ACCIDENTADOS]:[VEHICULOS_ACCIDENTADOS2]],"BUSETA") -> 0 | Z17: =COUNTIF(Tabla1[[#This Row],[VEHICULOS_ACCIDENTADOS]:[VEHICULOS_ACCIDENTADOS2]],"CAMION") -> 0 | AA17: =COUNTIF(Tabla1[[#This Row],[VEHICULOS_ACCIDENTADOS]:[VEHICULOS_ACCIDENTADOS2]],"TRACTOCAMION") -> 0 | AB17: =COUNTIF(Tabla1[[#This Row],[VEHICULOS_ACCIDENTADOS]:[VEHICULOS_ACCIDENTADOS2]],"VOLQUETA") -> 0 | AC17: =COUNTIF(Tabla1[[#This Row],[VEHICULOS_ACCIDENTADOS]:[VEHICULOS_ACCIDENTADOS2]],"BICICLETA") -> 1 | AD17: MASCULINO | AF17: =COUNTIF(Tabla1[[#This Row],[GENERO_MASCULINO]:[GENERO_FEMENINO]],"MASCULINO") -> 1 | AG17: =COUNTIF(Tabla1[[#This Row],[GENERO_MASCULINO]:[GENERO_FEMENINO]],"FEMENINO") -> 0 | AH17: 25 | AI17: 19 | AN17: 114 | AO17: =IFERROR(((VLOOKUP(Tabla1[[#This Row],[HIPOTESIS_1]],listas!$D$1:$E$105,2,FALSE))),"SIN INFORMACIÓN") -> Embriaguez aparente. | AP17: 127 | AQ17: =IFERROR(((VLOOKUP(Tabla1[[#This Row],[HIPOTESIS_2]],listas!$D$1:$E$105,2,FALSE))),"") -> Transitar en contravía. | AR17: =IF(HOUR(Tabla1[[#This Row],[HORA_ACCIDENTE]])<6,"MAÑANA", IF(HOUR(Tabla1[[#This Row],[HORA_ACCIDENTE]])<12,"MAÑANA", IF(HOUR(Tabla1[[#This Row],[HORA_ACCIDENTE]])<18,"TARDE","NOCHE"))) -> NOCHE
A18: 782 | B18: 0 | C18: 2 | D18: 0 | E18: =IF(D18>=1,"FALLECIDO",IF(C18>=1,"LESIONADO",IF(B18>=1,"SOLO DAÑO",""))) -> LESIONADO | F18: CARRERA 24 CALLE 21 | G18: 5.3401292 | H18: -72.391458 | I18: MOVILIDAD | J18: URBANO | K18: =UPPER(TEXT(M18,"YYYY")) -> 2024 | L18: =UPPER(TEXT(M18,"MMMM")) -> SEPTIEMBRE | M18: 45554 | N18: =UPPER(TEXT(M18,"DDDD")) -> JUEVES | O18: 0.63194444 | P18: CAMPERO | Q18: BICICLETA | R18: =COUNTIF(Tabla1[[#This Row],[VEHICULOS_ACCIDENTADOS]:[VEHICULOS_ACCIDENTADOS2]],"MOTOCICLETA") -> 0 | S18: =COUNTIF(Tabla1[[#This Row],[VEHICULOS_ACCIDENTADOS]:[VEHICULOS_ACCIDENTADOS2]],"MOTOCARRO") -> 0 | T18: =COUNTIF(Tabla1[[#This Row],[VEHICULOS_ACCIDENTADOS]:[VEHICULOS_ACCIDENTADOS2]],"AUTOMOVIL") -> 0 | U18: =COUNTIF(Tabla1[[#This Row],[VEHICULOS_ACCIDENTADOS]:[VEHICULOS_ACCIDENTADOS2]],"CAMPERO") -> 1 | V18: =COUNTIF(Tabla1[[#This Row],[VEHICULOS_ACCIDENTADOS]:[VEHICULOS_ACCIDENTADOS2]],"CAMIONETA") -> 0 | W18: =COUNTIF(Tabla1[[#This Row],[VEHICULOS_ACCIDENTADOS]:[VEHICULOS_ACCIDENTADOS2]],"MICROBUS") -> 0 | X18: =COUNTIF(Tabla1[[#This Row],[VEHICULOS_ACCIDENTADOS]:[VEHICULOS_ACCIDENTADOS2]],"BUS") -> 0 | Y18: =COUNTIF(Tabla1[[#This Row],[VEHICULOS_ACCIDENTADOS]:[VEHICULOS_ACCIDENTADOS2]],"BUSETA") -> 0 | Z18: =COUNTIF(Tabla1[[#This Row],[VEHICULOS_ACCIDENTADOS]:[VEHICULOS_ACCIDENTADOS2]],"CAMION") -> 0 | AA18: =COUNTIF(Tabla1[[#This Row],[VEHICULOS_ACCIDENTADOS]:[VEHICULOS_ACCIDENTADOS2]],"TRACTOCAMION") -> 0 | AB18: =COUNTIF(Tabla1[[#This Row],[VEHICULOS_ACCIDENTADOS]:[VEHICULOS_ACCIDENTADOS2]],"VOLQUETA") -> 0 | AC18: =COUNTIF(Tabla1[[#This Row],[VEHICULOS_ACCIDENTADOS]:[VEHICULOS_ACCIDENTADOS2]],"BICICLETA") -> 1 | AD18: MASCULINO | AE18: FEMENINO | AF18: =COUNTIF(Tabla1[[#This Row],[GENERO_MASCULINO]:[GENERO_FEMENINO]],"MASCULINO") -> 1 | AG18: =COUNTIF(Tabla1[[#This Row],[GENERO_MASCULINO]:[GENERO_FEMENINO]],"FEMENINO") -> 1 | AH18: 53 | AI18: 14 | AJ18: 3 | AN18: 90 | AO18: =IFERROR(((VLOOKUP(Tabla1[[#This Row],[HIPOTESIS_1]],listas!$D$1:$E$105,2,FALSE))),"SIN INFORMACIÓN") -> Transportar otra persona o cosas. | AP18: 127 | AQ18: =IFERROR(((VLOOKUP(Tabla1[[#This Row],[HIPOTESIS_2]],listas!$D$1:$E$105,2,FALSE))),"") -> Transitar en contravía. | AR18: =IF(HOUR(Tabla1[[#This Row],[HORA_ACCIDENTE]])<6,"MAÑANA", IF(HOUR(Tabla1[[#This Row],[HORA_ACCIDENTE]])<12,"MAÑANA", IF(HOUR(Tabla1[[#This Row],[HORA_ACCIDENTE]])<18,"TARDE","NOCHE"))) -> TARDE
A19: 65 | B19: 1 | C19: 0 | D19: 0 | E19: =IF(D19>=1,"FALLECIDO",IF(C19>=1,"LESIONADO",IF(B19>=1,"SOLO DAÑO",""))) -> SOLO DAÑO | F19: CARRERA 28 # 21 | G19: 5.3418444 | H19: -72.388286 | I19: MOVILIDAD | J19: URBANO | K19: =UPPER(TEXT(M19,"YYYY")) -> 2022 | L19: =UPPER(TEXT(M19,"MMMM")) -> FEBRERO | M19: 44615 | N19: =UPPER(TEXT(M19,"DDDD")) -> MIÉRCOLES | O19: 0.77083333 | P19: AUTOMOVIL | Q19: AUTOMOVIL | R19: =COUNTIF(Tabla1[[#This Row],[VEHICULOS_ACCIDENTADOS]:[VEHICULOS_ACCIDENTADOS2]],"MOTOCICLETA") -> 0 | S19: =COUNTIF(Tabla1[[#This Row],[VEHICULOS_ACCIDENTADOS]:[VEHICULOS_ACCIDENTADOS2]],"MOTOCARRO") -> 0 | T19: =COUNTIF(Tabla1[[#This Row],[VEHICULOS_ACCIDENTADOS]:[VEHICULOS_ACCIDENTADOS2]],"AUTOMOVIL") -> 2 | U19: =COUNTIF(Tabla1[[#This Row],[VEHICULOS_ACCIDENTADOS]:[VEHICULOS_ACCIDENTADOS2]],"CAMPERO") -> 0 | V19: =COUNTIF(Tabla1[[#This Row],[VEHICULOS_ACCIDENTADOS]:[VEHICULOS_ACCIDENTADOS2]],"CAMIONETA") -> 0 | W19: =COUNTIF(Tabla1[[#This Row],[VEHICULOS_ACCIDENTADOS]:[VEHICULOS_ACCIDENTADOS2]],"MICROBUS") -> 0 | X19: =COUNTIF(Tabla1[[#This Row],[VEHICULOS_ACCIDENTADOS]:[VEHICULOS_ACCIDENTADOS2]],"BUS") -> 0 | Y19: =COUNTIF(Tabla1[[#This Row],[VEHICULOS_ACCIDENTADOS]:[VEHICULOS_ACCIDENTADOS2]],"BUSETA") -> 0 | Z19: =COUNTIF(Tabla1[[#This Row],[VEHICULOS_ACCIDENTADOS]:[VEHICULOS_ACCIDENTADOS2]],"CAMION") -> 0 | AA19: =COUNTIF(Tabla1[[#This Row],[VEHICULOS_ACCIDENTADOS]:[VEHICULOS_ACCIDENTADOS2]],"TRACTOCAMION") -> 0 | AB19: =COUNTIF(Tabla1[[#This Row],[VEHICULOS_ACCIDENTADOS]:[VEHICULOS_ACCIDENTADOS2]],"VOLQUETA") -> 0 | AC19: =COUNTIF(Tabla1[[#This Row],[VEHICULOS_ACCIDENTADOS]:[VEHICULOS_ACCIDENTADOS2]],"BICICLETA") -> 0 | AD19: MASCULINO | AF19: =COUNTIF(Tabla1[[#This Row],[GENERO_MASCULINO]:[GENERO_FEMENINO]],"MASCULINO") -> 1 | AG19: =COUNTIF(Tabla1[[#This Row],[GENERO_MASCULINO]:[GENERO_FEMENINO]],"FEMENINO") -> 0 | AN19: 139 | AO19: =IFERROR(((VLOOKUP(Tabla1[[#This Row],[HIPOTESIS_1]],listas!$D$1:$E$105,2,FALSE))),"SIN INFORMACIÓN") -> Impericia en el manejo. | AP19: 127 | AQ19: =IFERROR(((VLOOKUP(Tabla1[[#This Row],[HIPOTESIS_2]],listas!$D$1:$E$105,2,FALSE))),"") -> Transitar en contravía. | AR19: =IF(HOUR(Tabla1[[#This Row],[HORA_ACCIDENTE]])<6,"MAÑANA", IF(HOUR(Tabla1[[#This Row],[HORA_ACCIDENTE]])<12,"MAÑANA", IF(HOUR(Tabla1[[#This Row],[HORA_ACCIDENTE]])<18,"TARDE","NOCHE"))) -> NOCHE
A20: 569 | B20: 1 | C20: 0 | D20: 0 | E20: =IF(D20>=1,"FALLECIDO",IF(C20>=1,"LESIONADO",IF(B20>=1,"SOLO DAÑO",""))) -> SOLO DAÑO | F20: CARRERA 43 CALLE 30 | G20: 5.34164 | H20: -72.372989 | I20: MOVILIDAD | J20: URBANO | K20: =UPPER(TEXT(M20,"YYYY")) -> 2023 | L20: =UPPER(TEXT(M20,"MMMM")) -> OCTUBRE | M20: 45206 | N20: =UPPER(TEXT(M20,"DDDD")) -> SÁBADO | O20: 0.91666667 | P20: MOTOCICLETA | Q20: MOTOCICLETA | R20: =COUNTIF(Tabla1[[#This Row],[VEHICULOS_ACCIDENTADOS]:[VEHICULOS_ACCIDENTADOS2]],"MOTOCICLETA") -> 2 | S20: =COUNTIF(Tabla1[[#This Row],[VEHICULOS_ACCIDENTADOS]:[VEHICULOS_ACCIDENTADOS2]],"MOTOCARRO") -> 0 | T20: =COUNTIF(Tabla1[[#This Row],[VEHICULOS_ACCIDENTADOS]:[VEHICULOS_ACCIDENTADOS2]],"AUTOMOVIL") -> 0 | U20: =COUNTIF(Tabla1[[#This Row],[VEHICULOS_ACCIDENTADOS]:[VEHICULOS_ACCIDENTADOS2]],"CAMPERO") -> 0 | V20: =COUNTIF(Tabla1[[#This Row],[VEHICULOS_ACCIDENTADOS]:[VEHICULOS_ACCIDENTADOS2]],"CAMIONETA") -> 0 | W20: =COUNTIF(Tabla1[[#This Row],[VEHICULOS_ACCIDENTADOS]:[VEHICULOS_ACCIDENTADOS2]],"MICROBUS") -> 0 | X20: =COUNTIF(Tabla1[[#This Row],[VEHICULOS_ACCIDENTADOS]:[VEHICULOS_ACCIDENTADOS2]],"BUS") -> 0 | Y20: =COUNTIF(Tabla1[[#This Row],[VEHICULOS_ACCIDENTADOS]:[VEHICULOS_ACCIDENTADOS2]],"BUSETA") -> 0 | Z20: =COUNTIF(Tabla1[[#This Row],[VEHICULOS_ACCIDENTADOS]:[VEHICULOS_ACCIDENTADOS2]],"CAMION") -> 0 | AA20: =COUNTIF(Tabla1[[#This Row],[VEHICULOS_ACCIDENTADOS]:[VEHICULOS_ACCIDENTADOS2]],"TRACTOCAMION") -> 0 | AB20: =COUNTIF(Tabla1[[#This Row],[VEHICULOS_ACCIDENTADOS]:[VEHICULOS_ACCIDENTADOS2]],"VOLQUETA") -> 0 | AC20: =COUNTIF(Tabla1[[#This Row],[VEHICULOS_ACCIDENTADOS]:[VEHICULOS_ACCIDENTADOS2]],"BICICLETA") -> 0 | AD20: MASCULINO | AF20: =COUNTIF(Tabla1[[#This Row],[GENERO_MASCULINO]:[GENERO_FEMENINO]],"MASCULINO") -> 1 | AG20: =COUNTIF(Tabla1[[#This Row],[GENERO_MASCULINO]:[GENERO_FEMENINO]],"FEMENINO") -> 0 | AN20: 115 | AO20: =IFERROR(((VLOOKUP(Tabla1[[#This Row],[HIPOTESIS_1]],listas!$D$1:$E$105,2,FALSE))),"SIN INFORMACIÓN") -> Embriaguez o Sustancias alucinogenas | AP20: 127 | AQ20: =IFERROR(((VLOOKUP(Tabla1[[#This Row],[HIPOTESIS_2]],listas!$D$1:$E$105,2,FALSE))),"") -> Transitar en contravía. | AR20: =IF(HOUR(Tabla1[[#This Row],[HORA_ACCIDENTE]])<6,"MAÑANA", IF(HOUR(Tabla1[[#This Row],[HORA_ACCIDENTE]])<12,"MAÑANA", IF(HOUR(Tabla1[[#This Row],[HORA_ACCIDENTE]])<18,"TARDE","NOCHE"))) -> NOCHE
A21: 856 | B21: 0 | C21: 1 | D21: 1 | E21: =IF(D21>=1,"FALLECIDO",IF(C21>=1,"LESIONADO",IF(B21>=1,"SOLO DAÑO",""))) -> FALLECIDO | F21: CARRERA 5 CALLE 6 CORREGIMIENTO DE MORICHAL | G21: 5.226339 | H21: -72.38925 | I21: MOVILIDAD | J21: RURAL | K21: =UPPER(TEXT(M21,"YYYY")) -> 2025 | L21: =UPPER(TEXT(M21,"MMMM")) -> ENERO | M21: 45673 | N21: =UPPER(TEXT(M21,"DDDD")) -> JUEVES | O21: 0.42361111 | P21: CAMION | Q21: MOTOCICLETA | R21: =COUNTIF(Tabla1[[#This Row],[VEHICULOS_ACCIDENTADOS]:[VEHICULOS_ACCIDENTADOS2]],"MOTOCICLETA") -> 1 | S21: =COUNTIF(Tabla1[[#This Row],[VEHICULOS_ACCIDENTADOS]:[VEHICULOS_ACCIDENTADOS2]],"MOTOCARRO") -> 0 | T21: =COUNTIF(Tabla1[[#This Row],[VEHICULOS_ACCIDENTADOS]:[VEHICULOS_ACCIDENTADOS2]],"AUTOMOVIL") -> 0 | U21: =COUNTIF(Tabla1[[#This Row],[VEHICULOS_ACCIDENTADOS]:[VEHICULOS_ACCIDENTADOS2]],"CAMPERO") -> 0 | V21: =COUNTIF(Tabla1[[#This Row],[VEHICULOS_ACCIDENTADOS]:[VEHICULOS_ACCIDENTADOS2]],"CAMIONETA") -> 0 | W21: =COUNTIF(Tabla1[[#This Row],[VEHICULOS_ACCIDENTADOS]:[VEHICULOS_ACCIDENTADOS2]],"MICROBUS") -> 0 | X21: =COUNTIF(Tabla1[[#This Row],[VEHICULOS_ACCIDENTADOS]:[VEHICULOS_ACCIDENTADOS2]],"BUS") -> 0 | Y21: =COUNTIF(Tabla1[[#This Row],[VEHICULOS_ACCIDENTADOS]:[VEHICULOS_ACCIDENTADOS2]],"BUSETA") -> 0 | Z21: =COUNTIF(Tabla1[[#This Row],[VEHICULOS_ACCIDENTADOS]:[VEHICULOS_ACCIDENTADOS2]],"CAMION") -> 1 | AA21: =COUNTIF(Tabla1[[#This Row],[VEHICULOS_ACCIDENTADOS]:[VEHICULOS_ACCIDENTADOS2]],"TRACTOCAMION") -> 0 | AB21: =COUNTIF(Tabla1[[#This Row],[VEHICULOS_ACCIDENTADOS]:[VEHICULOS_ACCIDENTADOS2]],"VOLQUETA") -> 0 | AC21: =COUNTIF(Tabla1[[#This Row],[VEHICULOS_ACCIDENTADOS]:[VEHICULOS_ACCIDENTADOS2]],"BICICLETA") -> 0 | AD21: MASCULINO | AE21: MASCULINO | AF21: =COUNTIF(Tabla1[[#This Row],[GENERO_MASCULINO]:[GENERO_FEMENINO]],"MASCULINO") -> 2 | AG21: =COUNTIF(Tabla1[[#This Row],[GENERO_MASCULINO]:[GENERO_FEMENINO]],"FEMENINO") -> 0 | AH21: 28 | AI21: 57 | AJ21: 51 | AM21: 28 | AN21: 114 | AO21: =IFERROR(((VLOOKUP(Tabla1[[#This Row],[HIPOTESIS_1]],listas!$D$1:$E$105,2,FALSE))),"SIN INFORMACIÓN") -> Embriaguez aparente. | AP21: 127 | AQ21: =IFERROR(((VLOOKUP(Tabla1[[#This Row],[HIPOTESIS_2]],listas!$D$1:$E$105,2,FALSE))),"") -> Transitar en contravía. | AR21: =IF(HOUR(Tabla1[[#This Row],[HORA_ACCIDENTE]])<6,"MAÑANA", IF(HOUR(Tabla1[[#This Row],[HORA_ACCIDENTE]])<12,"MAÑANA", IF(HOUR(Tabla1[[#This Row],[HORA_ACCIDENTE]])<18,"TARDE","NOCHE"))) -> MAÑANA
A22: 521 | B22: 0 | C22: 2 | D22: 0 | E22: =IF(D22>=1,"FALLECIDO",IF(C22>=1,"LESIONADO",IF(B22>=1,"SOLO DAÑO",""))) -> LESIONADO | F22: CARRERA 7B OESTE CALLE 65 | G22: 5.3005472 | H22: -72.419972 | I22: MOVILIDAD | J22: URBANO | K22: =UPPER(TEXT(M22,"YYYY")) -> 2023 | L22: =UPPER(TEXT(M22,"MMMM")) -> JULIO | M22: 45120 | N22: =UPPER(TEXT(M22,"DDDD")) -> JUEVES | O22: 0.77083333 | P22: MOTOCICLETA | R22: =COUNTIF(Tabla1[[#This Row],[VEHICULOS_ACCIDENTADOS]:[VEHICULOS_ACCIDENTADOS2]],"MOTOCICLETA") -> 1 | S22: =COUNTIF(Tabla1[[#This Row],[VEHICULOS_ACCIDENTADOS]:[VEHICULOS_ACCIDENTADOS2]],"MOTOCARRO") -> 0 | T22: =COUNTIF(Tabla1[[#This Row],[VEHICULOS_ACCIDENTADOS]:[VEHICULOS_ACCIDENTADOS2]],"AUTOMOVIL") -> 0 | U22: =COUNTIF(Tabla1[[#This Row],[VEHICULOS_ACCIDENTADOS]:[VEHICULOS_ACCIDENTADOS2]],"CAMPERO") -> 0 | V22: =COUNTIF(Tabla1[[#This Row],[VEHICULOS_ACCIDENTADOS]:[VEHICULOS_ACCIDENTADOS2]],"CAMIONETA") -> 0 | W22: =COUNTIF(Tabla1[[#This Row],[VEHICULOS_ACCIDENTADOS]:[VEHICULOS_ACCIDENTADOS2]],"MICROBUS") -> 0 | X22: =COUNTIF(Tabla1[[#This Row],[VEHICULOS_ACCIDENTADOS]:[VEHICULOS_ACCIDENTADOS2]],"BUS") -> 0 | Y22: =COUNTIF(Tabla1[[#This Row],[VEHICULOS_ACCIDENTADOS]:[VEHICULOS_ACCIDENTADOS2]],"BUSETA") -> 0 | Z22: =COUNTIF(Tabla1[[#This Row],[VEHICULOS_ACCIDENTADOS]:[VEHICULOS_ACCIDENTADOS2]],"CAMION") -> 0 | AA22: =COUNTIF(Tabla1[[#This Row],[VEHICULOS_ACCIDENTADOS]:[VEHICULOS_ACCIDENTADOS2]],"TRACTOCAMION") -> 0 | AB22: =COUNTIF(Tabla1[[#This Row],[VEHICULOS_ACCIDENTADOS]:[VEHICULOS_ACCIDENTADOS2]],"VOLQUETA") -> 0 | AC22: =COUNTIF(Tabla1[[#This Row],[VEHICULOS_ACCIDENTADOS]:[VEHICULOS_ACCIDENTADOS2]],"BICICLETA") -> 0 | AE22: FEMENINO | AF22: =COUNTIF(Tabla1[[#This Row],[GENERO_MASCULINO]:[GENERO_FEMENINO]],"MASCULINO") -> 0 | AG22: =COUNTIF(Tabla1[[#This Row],[GENERO_MASCULINO]:[GENERO_FEMENINO]],"FEMENINO") -> 1 | AH22: 24 | AK22: 77 | AN22: 139 | AO22: =IFERROR(((VLOOKUP(Tabla1[[#This Row],[HIPOTESIS_1]],listas!$D$1:$E$105,2,FALSE))),"SIN INFORMACIÓN") -> Impericia en el manejo. | AP22: 127 | AQ22: =IFERROR(((VLOOKUP(Tabla1[[#This Row],[HIPOTESIS_2]],listas!$D$1:$E$105,2,FALSE))),"") -> Transitar en contravía. | AR22: =IF(HOUR(Tabla1[[#This Row],[HORA_ACCIDENTE]])<6,"MAÑANA", IF(HOUR(Tabla1[[#This Row],[HORA_ACCIDENTE]])<12,"MAÑANA", IF(HOUR(Tabla1[[#This Row],[HORA_ACCIDENTE]])<18,"TARDE","NOCHE"))) -> NOCHE
A23: 541 | B23: 0 | C23: 0 | D23: 1 | E23: =IF(D23>=1,"FALLECIDO",IF(C23>=1,"LESIONADO",IF(B23>=1,"SOLO DAÑO",""))) -> FALLECIDO | F23: KM. 1 + 500 metros de la via yopal - aguazul | G23: 5.3200711 | H23: -72.417413 | I23: DITRA | J23: RURAL | K23: =UPPER(TEXT(M23,"YYYY")) -> 2023 | L23: =UPPER(TEXT(M23,"MMMM")) -> AGOSTO | M23: 45164 | N23: =UPPER(TEXT(M23,"DDDD")) -> SÁBADO | O23: 0.94444444 | P23: MOTOCICLETA | Q23: AUTOMOVIL | R23: =COUNTIF(Tabla1[[#This Row],[VEHICULOS_ACCIDENTADOS]:[VEHICULOS_ACCIDENTADOS2]],"MOTOCICLETA") -> 1 | S23: =COUNTIF(Tabla1[[#This Row],[VEHICULOS_ACCIDENTADOS]:[VEHICULOS_ACCIDENTADOS2]],"MOTOCARRO") -> 0 | T23: =COUNTIF(Tabla1[[#This Row],[VEHICULOS_ACCIDENTADOS]:[VEHICULOS_ACCIDENTADOS2]],"AUTOMOVIL") -> 1 | U23: =COUNTIF(Tabla1[[#This Row],[VEHICULOS_ACCIDENTADOS]:[VEHICULOS_ACCIDENTADOS2]],"CAMPERO") -> 0 | V23: =COUNTIF(Tabla1[[#This Row],[VEHICULOS_ACCIDENTADOS]:[VEHICULOS_ACCIDENTADOS2]],"CAMIONETA") -> 0 | W23: =COUNTIF(Tabla1[[#This Row],[VEHICULOS_ACCIDENTADOS]:[VEHICULOS_ACCIDENTADOS2]],"MICROBUS") -> 0 | X23: =COUNTIF(Tabla1[[#This Row],[VEHICULOS_ACCIDENTADOS]:[VEHICULOS_ACCIDENTADOS2]],"BUS") -> 0 | Y23: =COUNTIF(Tabla1[[#This Row],[VEHICULOS_ACCIDENTADOS]:[VEHICULOS_ACCIDENTADOS2]],"BUSETA") -> 0 | Z23: =COUNTIF(Tabla1[[#This Row],[VEHICULOS_ACCIDENTADOS]:[VEHICULOS_ACCIDENTADOS2]],"CAMION") -> 0 | AA23: =COUNTIF(Tabla1[[#This Row],[VEHICULOS_ACCIDENTADOS]:[VEHICULOS_ACCIDENTADOS2]],"TRACTOCAMION") -> 0 | AB23: =COUNTIF(Tabla1[[#This Row],[VEHICULOS_ACCIDENTADOS]:[VEHICULOS_ACCIDENTADOS2]],"VOLQUETA") -> 0 | AC23: =COUNTIF(Tabla1[[#This Row],[VEHICULOS_ACCIDENTADOS]:[VEHICULOS_ACCIDENTADOS2]],"BICICLETA") -> 0 | AE23: FEMENINO | AF23: =COUNTIF(Tabla1[[#This Row],[GENERO_MASCULINO]:[GENERO_FEMENINO]],"MASCULINO") -> 0 | AG23: =COUNTIF(Tabla1[[#This Row],[GENERO_MASCULINO]:[GENERO_FEMENINO]],"FEMENINO") -> 1 | AM23: 36 | AN23: 139 | AO23: =IFERROR(((VLOOKUP(Tabla1[[#This Row],[HIPOTESIS_1]],listas!$D$1:$E$105,2,FALSE))),"SIN INFORMACIÓN") -> Impericia en el manejo. | AP23: 127 | AQ23: =IFERROR(((VLOOKUP(Tabla1[[#This Row],[HIPOTESIS_2]],listas!$D$1:$E$105,2,FALSE))),"") -> Transitar en contravía. | AR23: =IF(HOUR(Tabla1[[#This Row],[HORA_ACCIDENTE]])<6,"MAÑANA", IF(HOUR(Tabla1[[#This Row],[HORA_ACCIDENTE]])<12,"MAÑANA", IF(HOUR(Tabla1[[#This Row],[HORA_ACCIDENTE]])<18,"TARDE","NOCHE"))) -> NOCHE
A24: 196 | B24: 0 | C24: 1 | D24: 0 | E24: =IF(D24>=1,"FALLECIDO",IF(C24>=1,"LESIONADO",IF(B24>=1,"SOLO DAÑO",""))) -> LESIONADO | F24: CARRERA 14A DIAGONAL 47 | G24: 5.3144972 | H24: -72.394403 | I24: MOVILIDAD | J24: URBANO | K24: =UPPER(TEXT(M24,"YYYY")) -> 2022 | L24: =UPPER(TEXT(M24,"MMMM")) -> MAYO | M24: 44708 | N24: =UPPER(TEXT(M24,"DDDD")) -> VIERNES | O24: 0.77083333 | P24: MOTOCICLETA | Q24: AUTOMOVIL | R24: =COUNTIF(Tabla1[[#This Row],[VEHICULOS_ACCIDENTADOS]:[VEHICULOS_ACCIDENTADOS2]],"MOTOCICLETA") -> 1 | S24: =COUNTIF(Tabla1[[#This Row],[VEHICULOS_ACCIDENTADOS]:[VEHICULOS_ACCIDENTADOS2]],"MOTOCARRO") -> 0 | T24: =COUNTIF(Tabla1[[#This Row],[VEHICULOS_ACCIDENTADOS]:[VEHICULOS_ACCIDENTADOS2]],"AUTOMOVIL") -> 1 | U24: =COUNTIF(Tabla1[[#This Row],[VEHICULOS_ACCIDENTADOS]:[VEHICULOS_ACCIDENTADOS2]],"CAMPERO") -> 0 | V24: =COUNTIF(Tabla1[[#This Row],[VEHICULOS_ACCIDENTADOS]:[VEHICULOS_ACCIDENTADOS2]],"CAMIONETA") -> 0 | W24: =COUNTIF(Tabla1[[#This Row],[VEHICULOS_ACCIDENTADOS]:[VEHICULOS_ACCIDENTADOS2]],"MICROBUS") -> 0 | X24: =COUNTIF(Tabla1[[#This Row],[VEHICULOS_ACCIDENTADOS]:[VEHICULOS_ACCIDENTADOS2]],"BUS") -> 0 | Y24: =COUNTIF(Tabla1[[#This Row],[VEHICULOS_ACCIDENTADOS]:[VEHICULOS_ACCIDENTADOS2]],"BUSETA") -> 0 | Z24: =COUNTIF(Tabla1[[#This Row],[VEHICULOS_ACCIDENTADOS]:[VEHICULOS_ACCIDENTADOS2]],"CAMION") -> 0 | AA24: =COUNTIF(Tabla1[[#This Row],[VEHICULOS_ACCIDENTADOS]:[VEHICULOS_ACCIDENTADOS2]],"TRACTOCAMION") -> 0 | AB24: =COUNTIF(Tabla1[[#This Row],[VEHICULOS_ACCIDENTADOS]:[VEHICULOS_ACCIDENTADOS2]],"VOLQUETA") -> 0 | AC24: =COUNTIF(Tabla1[[#This Row],[VEHICULOS_ACCIDENTADOS]:[VEHICULOS_ACCIDENTADOS2]],"BICICLETA") -> 0 | AD24: MASCULINO | AF24: =COUNTIF(Tabla1[[#This Row],[GENERO_MASCULINO]:[GENERO_FEMENINO]],"MASCULINO") -> 1 | AG24: =COUNTIF(Tabla1[[#This Row],[GENERO_MASCULINO]:[GENERO_FEMENINO]],"FEMENINO") -> 0 | AH24: 16 | AN24: 139 | AO24: =IFERROR(((VLOOKUP(Tabla1[[#This Row],[HIPOTESIS_1]],listas!$D$1:$E$105,2,FALSE))),"SIN INFORMACIÓN") -> Impericia en el manejo. | AP24: 93 | AQ24: =IFERROR(((VLOOKUP(Tabla1[[#This Row],[HIPOTESIS_2]],listas!$D$1:$E$105,2,FALSE))),"") -> Transitar distante de la acera u orilla de la calzada. | AR24: =IF(HOUR(Tabla1[[#This Row],[HORA_ACCIDENTE]])<6,"MAÑANA", IF(HOUR(Tabla1[[#This Row],[HORA_ACCIDENTE]])<12,"MAÑANA", IF(HOUR(Tabla1[[#This Row],[HORA_ACCIDENTE]])<18,"TARDE","NOCHE"))) -> NOCHE
A25: 146 | B25: 0 | C25: 1 | D25: 0 | E25: =IF(D25>=1,"FALLECIDO",IF(C25>=1,"LESIONADO",IF(B25>=1,"SOLO DAÑO",""))) -> LESIONADO | F25: CARRERA 21 CALLE 26A | G25: 5.3341333 | H25: -72.391961 | I25: MOVILIDAD | J25: URBANO | K25: =UPPER(TEXT(M25,"YYYY")) -> 2022 | L25: =UPPER(TEXT(M25,"MMMM")) -> ABRIL | M25: 44675 | N25: =UPPER(TEXT(M25,"DDDD")) -> DOMINGO | O25: 0.8125 | P25: MOTOCICLETA | Q25: MOTOCICLETA | R25: =COUNTIF(Tabla1[[#This Row],[VEHICULOS_ACCIDENTADOS]:[VEHICULOS_ACCIDENTADOS2]],"MOTOCICLETA") -> 2 | S25: =COUNTIF(Tabla1[[#This Row],[VEHICULOS_ACCIDENTADOS]:[VEHICULOS_ACCIDENTADOS2]],"MOTOCARRO") -> 0 | T25: =COUNTIF(Tabla1[[#This Row],[VEHICULOS_ACCIDENTADOS]:[VEHICULOS_ACCIDENTADOS2]],"AUTOMOVIL") -> 0 | U25: =COUNTIF(Tabla1[[#This Row],[VEHICULOS_ACCIDENTADOS]:[VEHICULOS_ACCIDENTADOS2]],"CAMPERO") -> 0 | V25: =COUNTIF(Tabla1[[#This Row],[VEHICULOS_ACCIDENTADOS]:[VEHICULOS_ACCIDENTADOS2]],"CAMIONETA") -> 0 | W25: =COUNTIF(Tabla1[[#This Row],[VEHICULOS_ACCIDENTADOS]:[VEHICULOS_ACCIDENTADOS2]],"MICROBUS") -> 0 | X25: =COUNTIF(Tabla1[[#This Row],[VEHICULOS_ACCIDENTADOS]:[VEHICULOS_ACCIDENTADOS2]],"BUS") -> 0 | Y25: =COUNTIF(Tabla1[[#This Row],[VEHICULOS_ACCIDENTADOS]:[VEHICULOS_ACCIDENTADOS2]],"BUSETA") -> 0 | Z25: =COUNTIF(Tabla1[[#This Row],[VEHICULOS_ACCIDENTADOS]:[VEHICULOS_ACCIDENTADOS2]],"CAMION") -> 0 | AA25: =COUNTIF(Tabla1[[#This Row],[VEHICULOS_ACCIDENTADOS]:[VEHICULOS_ACCIDENTADOS2]],"TRACTOCAMION") -> 0 | AB25: =COUNTIF(Tabla1[[#This Row],[VEHICULOS_ACCIDENTADOS]:[VEHICULOS_ACCIDENTADOS2]],"VOLQUETA") -> 0 | AC25: =COUNTIF(Tabla1[[#This Row],[VEHICULOS_ACCIDENTADOS]:[VEHICULOS_ACCIDENTADOS2]],"BICICLETA") -> 0 | AE25: FEMENINO | AF25: =COUNTIF(Tabla1[[#This Row],[GENERO_MASCULINO]:[GENERO_FEMENINO]],"MASCULINO") -> 0 | AG25: =COUNTIF(Tabla1[[#This Row],[GENERO_MASCULINO]:[GENERO_FEMENINO]],"FEMENINO") -> 1 | AH25: 23 | AN25: 121 | AO25: =IFERROR(((VLOOKUP(Tabla1[[#This Row],[HIPOTESIS_1]],listas!$D$1:$E$105,2,FALSE))),"SIN INFORMACIÓN") -> No mantener distancia de seguridad. | AP25: 93 | AQ25: =IFERROR(((VLOOKUP(Tabla1[[#This Row],[HIPOTESIS_2]],listas!$D$1:$E$105,2,FALSE))),"") -> Transitar distante de la acera u orilla de la calzada. | AR25: =IF(HOUR(Tabla1[[#This Row],[HORA_ACCIDENTE]])<6,"MAÑANA", IF(HOUR(Tabla1[[#This Row],[HORA_ACCIDENTE]])<12,"MAÑANA", IF(HOUR(Tabla1[[#This Row],[HORA_ACCIDENTE]])<18,"TARDE","NOCHE"))) -> NOCHE
